<?xml version="1.0" ?>
<sdf version='1.6'>
  <world name='default'>
    <model name='ground_plane'>
      <static>1</static>
      <link name='link'>
        <collision name='collision'>
          <geometry>
            <plane>
              <normal>0 0 1</normal>
              <size>100 100</size>
            </plane>
          </geometry>
          <surface>
            <friction>
              <ode>
                <mu>100</mu>
                <mu2>50</mu2>
              </ode>
              <torsional>
                <ode/>
              </torsional>
            </friction>
            <contact>
              <ode/>
            </contact>
            <bounce/>
          </surface>
          <max_contacts>10</max_contacts>
        </collision>
        <visual name='visual'>
          <cast_shadows>0</cast_shadows>
          <geometry>
            <plane>
              <normal>0 0 1</normal>
              <size>100 100</size>
            </plane>
          </geometry>
          <material>
            <script>
              <uri>file://media/materials/scripts/gazebo.material</uri>
              <name>Gazebo/Grey</name>
            </script>
          </material>
        </visual>
        <self_collide>0</self_collide>
        <kinematic>0</kinematic>
        <gravity>1</gravity>
      </link>
    </model>
    <light name='sun' type='directional'>
      <cast_shadows>1</cast_shadows>
      <pose frame=''>0 0 10 0 -0 0</pose>
      <diffuse>0.8 0.8 0.8 1</diffuse>
      <specular>0.1 0.1 0.1 1</specular>
      <attenuation>
        <range>1000</range>
        <constant>0.9</constant>
        <linear>0.01</linear>
        <quadratic>0.001</quadratic>
      </attenuation>
      <direction>-0.5 0.5 -1</direction>
    </light>
    <model name='sr_top_view_camera'>
      <static>1</static>
      <link name='link'>
        <inertial>
          <mass>0.1</mass>
        </inertial>
        <visual name='visual'>
          <material>
            <ambient>0 1 0 1</ambient>
            <diffuse>0 1 0 1</diffuse>
          </material>
          <geometry>
            <box>
              <size>0.1 0.1 0.1</size>
            </box>
          </geometry>
        </visual>
        <collision name='collision'>
          <geometry>
            <box>
              <size>0.1 0.1 0.1</size>
            </box>
          </geometry>
          <max_contacts>10</max_contacts>
          <surface>
            <contact>
              <ode/>
            </contact>
            <bounce/>
            <friction>
              <torsional>
                <ode/>
              </torsional>
              <ode/>
            </friction>
          </surface>
        </collision>
        <sensor name='sr_sensor_top_view_camera' type='camera'>
          <always_on>1</always_on>
          <update_rate>24</update_rate>
          <visualize>1</visualize>
          <plugin name='sr_sensor_top_view_camera_plugin' filename='libgazeboCameraPublisher.so'/>
          <camera name='__default__'>
            <horizontal_fov>2</horizontal_fov>
            <image>
              <width>800</width>
              <height>600</height>
            </image>
            <clip>
              <near>0.1</near>
              <far>200</far>
            </clip>
            <save enabled='0'>
              <path>/home/DUC/test/save_frame</path>
            </save>
          </camera>
        </sensor>
        <self_collide>0</self_collide>
        <kinematic>0</kinematic>
        <gravity>1</gravity>
      </link>
    </model>
    <physics name='default_physics' default='0' type='ode'>
      <ode>
        <solver>
          <type>quick</type>
          <iters>100</iters>
          <precon_iters>0</precon_iters>
          <sor>1</sor>
          <use_dynamic_moi_rescaling>0</use_dynamic_moi_rescaling>
        </solver>
        <constraints>
          <cfm>0</cfm>
          <erp>0.2</erp>
          <contact_max_correcting_vel>0</contact_max_correcting_vel>
          <contact_surface_layer>0</contact_surface_layer>
        </constraints>
      </ode>
      <real_time_update_rate>0</real_time_update_rate>
      <max_step_size>0.001</max_step_size>
      <real_time_factor>1</real_time_factor>
    </physics>
    <gravity>0 0 -9.81</gravity>
    <magnetic_field>6e-06 2.3e-05 -4.2e-05</magnetic_field>
    <atmosphere type='adiabatic'/>
    <scene>
      <ambient>0.4 0.4 0.4 1</ambient>
      <background>0.7 0.7 0.7 1</background>
      <shadows>1</shadows>
    </scene>
    <spherical_coordinates>
      <surface_model>EARTH_WGS84</surface_model>
      <latitude_deg>0</latitude_deg>
      <longitude_deg>0</longitude_deg>
      <elevation>0</elevation>
      <heading_deg>0</heading_deg>
    </spherical_coordinates>
    <model name='shadowhand_motor'>
      <link name='rh_forearm'>
        <pose frame=''>0 0 0 0 -0 0</pose>
        <inertial>
          <pose frame=''>0 0 0.09 0 -0 0</pose>
          <mass>3</mass>
          <inertia>
            <ixx>0.0138</ixx>
            <ixy>0</ixy>
            <ixz>0</ixz>
            <iyy>0.0138</iyy>
            <iyz>0</iyz>
            <izz>0.00744</izz>
          </inertia>
        </inertial>
        <collision name='rh_forearm_collision'>
          <pose frame=''>0 0 0.092 0 -0 0</pose>
          <geometry>
            <cylinder>
              <length>0.184</length>
              <radius>0.07</radius>
            </cylinder>
          </geometry>
          <surface>
            <contact>
              <ode/>
            </contact>
            <friction>
              <ode/>
              <torsional>
                <ode/>
              </torsional>
            </friction>
            <bounce/>
          </surface>
          <max_contacts>10</max_contacts>
        </collision>
        <collision name='rh_forearm_collision_1'>
          <pose frame=''>0 -0.01 0.181 0 0.78 0</pose>
          <geometry>
            <box>
              <size>0.07 0.07 0.07</size>
            </box>
          </geometry>
          <surface>
            <contact>
              <ode/>
            </contact>
            <friction>
              <ode/>
              <torsional>
                <ode/>
              </torsional>
            </friction>
            <bounce/>
          </surface>
          <max_contacts>10</max_contacts>
        </collision>
        <visual name='rh_forearm_visual'>
          <pose frame=''>0 0 0 0 -0 0</pose>
          <geometry>
            <mesh>
              <scale>1 1 1</scale>
              <uri>/home/brhm/DUC/RobotArm/src/my_arm/meshes/shadow_hand/hand/forearm.dae</uri>
            </mesh>
          </geometry>
          <material>
            <script>
              <uri>__default__</uri>
              <name>__default__</name>
            </script>
          </material>
        </visual>
        <gravity>1</gravity>
        <velocity_decay/>
        <self_collide>0</self_collide>
        <kinematic>0</kinematic>
      </link>
      <joint name='rh_world_joint' type='revolute'>
        <child>rh_forearm</child>
        <parent>world</parent>
        <axis>
          <limit>
            <lower>0</lower>
            <upper>0</upper>
          </limit>
          <dynamics>
            <damping>0</damping>
            <friction>0</friction>
            <spring_reference>0</spring_reference>
            <spring_stiffness>0</spring_stiffness>
          </dynamics>
          <use_parent_model_frame>1</use_parent_model_frame>
          <xyz>0 0 1</xyz>
        </axis>
      </joint>
      <link name='rh_wrist'>
        <pose frame=''>0 -0.01 0.213 0 -0 0</pose>
        <inertial>
          <pose frame=''>0 0 0.029 0 -0 0</pose>
          <mass>0.1</mass>
          <inertia>
            <ixx>3.5e-05</ixx>
            <ixy>0</ixy>
            <ixz>0</ixz>
            <iyy>6.4e-05</iyy>
            <iyz>0</iyz>
            <izz>4.38e-05</izz>
          </inertia>
        </inertial>
        <collision name='rh_wrist_collision'>
          <pose frame=''>0 0 0 -3.14159 1.57079 1.57079</pose>
          <geometry>
            <cylinder>
              <length>0.03</length>
              <radius>0.0135</radius>
            </cylinder>
          </geometry>
          <surface>
            <contact>
              <ode/>
            </contact>
            <friction>
              <ode/>
              <torsional>
                <ode/>
              </torsional>
            </friction>
            <bounce/>
          </surface>
          <max_contacts>10</max_contacts>
        </collision>
        <collision name='rh_wrist_collision_1'>
          <pose frame=''>-0.026 0 0.034 3.14159 1.57079 3.14159</pose>
          <geometry>
            <cylinder>
              <length>0.01</length>
              <radius>0.011</radius>
            </cylinder>
          </geometry>
          <surface>
            <contact>
              <ode/>
            </contact>
            <friction>
              <ode/>
              <torsional>
                <ode/>
              </torsional>
            </friction>
            <bounce/>
          </surface>
          <max_contacts>10</max_contacts>
        </collision>
        <collision name='rh_wrist_collision_2'>
          <pose frame=''>0.031 0 0.034 3.14159 1.57079 3.14159</pose>
          <geometry>
            <cylinder>
              <length>0.01</length>
              <radius>0.011</radius>
            </cylinder>
          </geometry>
          <surface>
            <contact>
              <ode/>
            </contact>
            <friction>
              <ode/>
              <torsional>
                <ode/>
              </torsional>
            </friction>
            <bounce/>
          </surface>
          <max_contacts>10</max_contacts>
        </collision>
        <collision name='rh_wrist_collision_3'>
          <pose frame=''>-0.021 0 0.011 0 0.7854 0</pose>
          <geometry>
            <box>
              <size>0.027 0.018 0.01</size>
            </box>
          </geometry>
          <surface>
            <contact>
              <ode/>
            </contact>
            <friction>
              <ode/>
              <torsional>
                <ode/>
              </torsional>
            </friction>
            <bounce/>
          </surface>
          <max_contacts>10</max_contacts>
        </collision>
        <collision name='rh_wrist_collision_4'>
          <pose frame=''>0.026 0 0.01 0 -0.7854 0</pose>
          <geometry>
            <box>
              <size>0.027 0.018 0.01</size>
            </box>
          </geometry>
          <surface>
            <contact>
              <ode/>
            </contact>
            <friction>
              <ode/>
              <torsional>
                <ode/>
              </torsional>
            </friction>
            <bounce/>
          </surface>
          <max_contacts>10</max_contacts>
        </collision>
        <visual name='rh_wrist_visual'>
          <pose frame=''>0 0 0 0 -0 0</pose>
          <geometry>
            <mesh>
              <scale>1 1 1</scale>
              <uri>/home/brhm/DUC/RobotArm/src/my_arm/meshes/shadow_hand/hand/wrist.dae</uri>
            </mesh>
          </geometry>
          <material>
            <script>
              <name>Gazebo/White</name>
              <uri>file://media/materials/scripts/gazebo.material</uri>
            </script>
          </material>
        </visual>
        <gravity>1</gravity>
        <velocity_decay/>
        <self_collide>0</self_collide>
        <kinematic>0</kinematic>
      </link>
      <joint name='rh_WRJ2' type='revolute'>
        <child>rh_wrist</child>
        <parent>rh_forearm</parent>
        <axis>
          <xyz>0 1 0</xyz>
          <limit>
            <lower>-0.523599</lower>
            <upper>0.174533</upper>
            <effort>10</effort>
            <velocity>2</velocity>
          </limit>
          <dynamics>
            <damping>0.1</damping>
            <friction>0</friction>
            <spring_reference>0</spring_reference>
            <spring_stiffness>0</spring_stiffness>
          </dynamics>
          <use_parent_model_frame>1</use_parent_model_frame>
        </axis>
        <physics>
          <provide_feedback>1</provide_feedback>
          <ode>
            <provide_feedback>1</provide_feedback>
            <implicit_spring_damper>1</implicit_spring_damper>
            <cfm_damping>1</cfm_damping>
            <limit>
              <cfm>0</cfm>
              <erp>0.2</erp>
            </limit>
          </ode>
        </physics>
      </joint>
      <link name='rh_palm'>
        <pose frame=''>0 -0.01 0.247 0 -0 0</pose>
        <inertial>
          <pose frame=''>0 0 0.035 0 -0 0</pose>
          <mass>0.3</mass>
          <inertia>
            <ixx>0.0003581</ixx>
            <ixy>0</ixy>
            <ixz>0</ixz>
            <iyy>0.0005287</iyy>
            <iyz>0</iyz>
            <izz>0.000191</izz>
          </inertia>
        </inertial>
        <collision name='rh_palm_collision'>
          <pose frame=''>0.011 0.0085 0.038 0 -0 0</pose>
          <geometry>
            <box>
              <size>0.062 0.007 0.098</size>
            </box>
          </geometry>
          <surface>
            <contact>
              <ode/>
            </contact>
            <friction>
              <ode/>
              <torsional>
                <ode/>
              </torsional>
            </friction>
            <bounce/>
          </surface>
          <max_contacts>10</max_contacts>
        </collision>
        <collision name='rh_palm_collision_1'>
          <pose frame=''>-0.002 -0.0035 0.038 0 -0 0</pose>
          <geometry>
            <box>
              <size>0.036 0.017 0.098</size>
            </box>
          </geometry>
          <surface>
            <contact>
              <ode/>
            </contact>
            <friction>
              <ode/>
              <torsional>
                <ode/>
              </torsional>
            </friction>
            <bounce/>
          </surface>
          <max_contacts>10</max_contacts>
        </collision>
        <collision name='rh_palm_collision_2'>
          <pose frame=''>0.029 -0.0035 0.082 0 -0 0</pose>
          <geometry>
            <box>
              <size>0.026 0.017 0.01</size>
            </box>
          </geometry>
          <surface>
            <contact>
              <ode/>
            </contact>
            <friction>
              <ode/>
              <torsional>
                <ode/>
              </torsional>
            </friction>
            <bounce/>
          </surface>
          <max_contacts>10</max_contacts>
        </collision>
        <collision name='rh_palm_collision_3'>
          <pose frame=''>0.0265 -0.001 0.07 0.2 -0 0.25</pose>
          <geometry>
            <box>
              <size>0.026 0.014 0.018</size>
            </box>
          </geometry>
          <surface>
            <contact>
              <ode/>
            </contact>
            <friction>
              <ode/>
              <torsional>
                <ode/>
              </torsional>
            </friction>
            <bounce/>
          </surface>
          <max_contacts>10</max_contacts>
        </collision>
        <collision name='rh_palm_collision_4'>
          <pose frame=''>0.0315 -0.0085 0.001 0 -0 0</pose>
          <geometry>
            <box>
              <size>0.021 0.027 0.024</size>
            </box>
          </geometry>
          <surface>
            <contact>
              <ode/>
            </contact>
            <friction>
              <ode/>
              <torsional>
                <ode/>
              </torsional>
            </friction>
            <bounce/>
          </surface>
          <max_contacts>10</max_contacts>
        </collision>
        <collision name='rh_palm_collision_5'>
          <pose frame=''>0.0125 -0.015 0.009 0 0 -0.48</pose>
          <geometry>
            <box>
              <size>0.022 0.005 0.04</size>
            </box>
          </geometry>
          <surface>
            <contact>
              <ode/>
            </contact>
            <friction>
              <ode/>
              <torsional>
                <ode/>
              </torsional>
            </friction>
            <bounce/>
          </surface>
          <max_contacts>10</max_contacts>
        </collision>
        <collision name='rh_palm_collision_6'>
          <pose frame=''>0.011 0 0.089 0 -0 0</pose>
          <geometry>
            <box>
              <size>0.018 0.024 0.004</size>
            </box>
          </geometry>
          <surface>
            <contact>
              <ode/>
            </contact>
            <friction>
              <ode/>
              <torsional>
                <ode/>
              </torsional>
            </friction>
            <bounce/>
          </surface>
          <max_contacts>10</max_contacts>
        </collision>
        <collision name='rh_palm_collision_7'>
          <pose frame=''>-0.03 0 0.009 0 -0 0</pose>
          <geometry>
            <box>
              <size>0.02 0.024 0.04</size>
            </box>
          </geometry>
          <surface>
            <contact>
              <ode/>
            </contact>
            <friction>
              <ode/>
              <torsional>
                <ode/>
              </torsional>
            </friction>
            <bounce/>
          </surface>
          <max_contacts>10</max_contacts>
        </collision>
        <visual name='rh_palm_visual'>
          <pose frame=''>0 0 0 0 -0 0</pose>
          <geometry>
            <mesh>
              <scale>1 1 1</scale>
              <uri>/home/brhm/DUC/RobotArm/src/my_arm/meshes/shadow_hand/hand/palm.dae</uri>
            </mesh>
          </geometry>
          <material>
            <script>
              <uri>__default__</uri>
              <name>__default__</name>
            </script>
          </material>
        </visual>
        <gravity>1</gravity>
        <velocity_decay/>
        <self_collide>0</self_collide>
        <sensor name='rh_palm_contact' type='contact'>
          <always_on>1</always_on>
          <update_rate>1000</update_rate>
          <contact>
            <collision>rh_palm_collision</collision>
            <topic>rh_palm_collision</topic>
          </contact>
          <plugin name='rh_palm_gazebo_ros_bumper_controller' filename='libgazebo_ros_bumper.so'>
            <alwaysOn>true</alwaysOn>
            <frameName>rh_palm</frameName>
            <updateRate>100.0</updateRate>
            <bumperTopicName>contacts/rh_palm</bumperTopicName>
            <robotNamespace>/</robotNamespace>
          </plugin>
        </sensor>
        <kinematic>0</kinematic>
      </link>
      <joint name='rh_WRJ1' type='revolute'>
        <child>rh_palm</child>
        <parent>rh_wrist</parent>
        <axis>
          <xyz>1 0 0</xyz>
          <limit>
            <lower>-0.698132</lower>
            <upper>0.488692</upper>
            <effort>30</effort>
            <velocity>2</velocity>
          </limit>
          <dynamics>
            <damping>0.1</damping>
            <friction>0</friction>
            <spring_reference>0</spring_reference>
            <spring_stiffness>0</spring_stiffness>
          </dynamics>
          <use_parent_model_frame>1</use_parent_model_frame>
        </axis>
        <physics>
          <provide_feedback>1</provide_feedback>
          <ode>
            <provide_feedback>1</provide_feedback>
            <implicit_spring_damper>1</implicit_spring_damper>
            <cfm_damping>1</cfm_damping>
            <limit>
              <cfm>0</cfm>
              <erp>0.2</erp>
            </limit>
          </ode>
        </physics>
      </joint>
      <link name='rh_ffknuckle'>
        <pose frame=''>0.033 -0.01 0.342 0 -0 0</pose>
        <inertial>
          <pose frame=''>0 0 0 0 -0 0</pose>
          <mass>0.008</mass>
          <inertia>
            <ixx>2.6e-07</ixx>
            <ixy>0</ixy>
            <ixz>0</ixz>
            <iyy>2.6e-07</iyy>
            <iyz>0</iyz>
            <izz>3.2e-07</izz>
          </inertia>
        </inertial>
        <collision name='rh_ffknuckle_collision'>
          <pose frame=''>0 0 0 3.14159 1.57079 3.14159</pose>
          <geometry>
            <cylinder>
              <length>0.014</length>
              <radius>0.007</radius>
            </cylinder>
          </geometry>
          <surface>
            <contact>
              <ode/>
            </contact>
            <friction>
              <ode/>
              <torsional>
                <ode/>
              </torsional>
            </friction>
            <bounce/>
          </surface>
          <max_contacts>10</max_contacts>
        </collision>
        <visual name='rh_ffknuckle_visual'>
          <pose frame=''>0 0 0.0005 0 -0 0</pose>
          <geometry>
            <mesh>
              <scale>1 1 1</scale>
              <uri>/home/brhm/DUC/RobotArm/src/my_arm/meshes/shadow_hand/hand/knuckle.dae</uri>
            </mesh>
          </geometry>
          <material>
            <script>
              <name>Gazebo/Grey</name>
              <uri>file://media/materials/scripts/gazebo.material</uri>
            </script>
          </material>
        </visual>
        <gravity>1</gravity>
        <velocity_decay/>
        <self_collide>0</self_collide>
        <sensor name='rh_ffknuckle_contact' type='contact'>
          <always_on>1</always_on>
          <update_rate>1000</update_rate>
          <contact>
            <collision>rh_ffknuckle_collision</collision>
            <topic>rh_ffknuckle_collision</topic>
          </contact>
          <plugin name='rh_ffknuckle_gazebo_ros_bumper_controller' filename='libgazebo_ros_bumper.so'>
            <alwaysOn>true</alwaysOn>
            <frameName>rh_ffknuckle</frameName>
            <updateRate>100.0</updateRate>
            <bumperTopicName>contacts/rh_ff/knuckle</bumperTopicName>
            <robotNamespace>/</robotNamespace>
          </plugin>
        </sensor>
        <kinematic>0</kinematic>
      </link>
      <joint name='rh_FFJ4' type='revolute'>
        <child>rh_ffknuckle</child>
        <parent>rh_palm</parent>
        <axis>
          <xyz>0 -1 0</xyz>
          <limit>
            <lower>-0.349066</lower>
            <upper>0.349066</upper>
            <effort>2</effort>
            <velocity>2</velocity>
          </limit>
          <dynamics>
            <damping>0.1</damping>
            <friction>0</friction>
            <spring_reference>0</spring_reference>
            <spring_stiffness>0</spring_stiffness>
          </dynamics>
          <use_parent_model_frame>1</use_parent_model_frame>
        </axis>
        <physics>
          <provide_feedback>1</provide_feedback>
          <ode>
            <provide_feedback>1</provide_feedback>
            <implicit_spring_damper>1</implicit_spring_damper>
            <cfm_damping>1</cfm_damping>
            <limit>
              <cfm>0</cfm>
              <erp>0.2</erp>
            </limit>
          </ode>
        </physics>
      </joint>
      <link name='rh_ffproximal'>
        <pose frame=''>0.033 -0.01 0.342 0 -0 0</pose>
        <inertial>
          <pose frame=''>0 0 0.0225 0 -0 0</pose>
          <mass>0.03</mass>
          <inertia>
            <ixx>9.8e-06</ixx>
            <ixy>0</ixy>
            <ixz>0</ixz>
            <iyy>1e-05</iyy>
            <iyz>0</iyz>
            <izz>1.8e-06</izz>
          </inertia>
        </inertial>
        <collision name='rh_ffproximal_collision'>
          <pose frame=''>0 0 0.025 0 -0 0</pose>
          <geometry>
            <cylinder>
              <length>0.04</length>
              <radius>0.007</radius>
            </cylinder>
          </geometry>
          <surface>
            <contact>
              <ode/>
            </contact>
            <friction>
              <ode/>
              <torsional>
                <ode/>
              </torsional>
            </friction>
            <bounce/>
          </surface>
          <max_contacts>10</max_contacts>
        </collision>
        <visual name='rh_ffproximal_visual'>
          <pose frame=''>0 0 0 0 -0 0</pose>
          <geometry>
            <mesh>
              <scale>1 1 1</scale>
              <uri>/home/brhm/DUC/RobotArm/src/my_arm/meshes/shadow_hand/hand/F3.dae</uri>
            </mesh>
          </geometry>
          <material>
            <script>
              <uri>__default__</uri>
              <name>__default__</name>
            </script>
          </material>
        </visual>
        <gravity>1</gravity>
        <velocity_decay/>
        <self_collide>1</self_collide>
        <sensor name='rh_ffproximal_contact' type='contact'>
          <always_on>1</always_on>
          <update_rate>1000</update_rate>
          <contact>
            <collision>rh_ffproximal_collision</collision>
            <topic>rh_ffproximal_collision</topic>
          </contact>
          <plugin name='rh_ffproximal_gazebo_ros_bumper_controller' filename='libgazebo_ros_bumper.so'>
            <alwaysOn>true</alwaysOn>
            <frameName>rh_ffproximal</frameName>
            <updateRate>100.0</updateRate>
            <bumperTopicName>contacts/rh_ff/proximal</bumperTopicName>
            <robotNamespace>/</robotNamespace>
          </plugin>
        </sensor>
        <kinematic>0</kinematic>
      </link>
      <joint name='rh_FFJ3' type='revolute'>
        <child>rh_ffproximal</child>
        <parent>rh_ffknuckle</parent>
        <axis>
          <xyz>1 0 0</xyz>
          <limit>
            <lower>0</lower>
            <upper>1.5708</upper>
            <effort>2</effort>
            <velocity>2</velocity>
          </limit>
          <dynamics>
            <damping>0.1</damping>
            <friction>0</friction>
            <spring_reference>0</spring_reference>
            <spring_stiffness>0</spring_stiffness>
          </dynamics>
          <use_parent_model_frame>1</use_parent_model_frame>
        </axis>
        <physics>
          <provide_feedback>1</provide_feedback>
          <ode>
            <provide_feedback>1</provide_feedback>
            <implicit_spring_damper>1</implicit_spring_damper>
            <cfm_damping>1</cfm_damping>
            <limit>
              <cfm>0</cfm>
              <erp>0.2</erp>
            </limit>
          </ode>
        </physics>
      </joint>
      <link name='rh_ffmiddle'>
        <pose frame=''>0.033 -0.01 0.387 0 -0 0</pose>
        <inertial>
          <pose frame=''>0 0 0.0125 0 -0 0</pose>
          <mass>0.017</mass>
          <inertia>
            <ixx>2.6e-06</ixx>
            <ixy>0</ixy>
            <ixz>0</ixz>
            <iyy>2.7e-06</iyy>
            <iyz>0</iyz>
            <izz>8.7e-07</izz>
          </inertia>
        </inertial>
        <collision name='rh_ffmiddle_collision'>
          <pose frame=''>0 0 0.0125 0 -0 0</pose>
          <geometry>
            <cylinder>
              <length>0.025</length>
              <radius>0.007</radius>
            </cylinder>
          </geometry>
          <surface>
            <contact>
              <ode/>
            </contact>
            <friction>
              <ode/>
              <torsional>
                <ode/>
              </torsional>
            </friction>
            <bounce/>
          </surface>
          <max_contacts>10</max_contacts>
        </collision>
        <collision name='rh_ffmiddle_collision_1'>
          <pose frame=''>0 0 0 0 -0 0</pose>
          <geometry>
            <sphere>
              <radius>0.007</radius>
            </sphere>
          </geometry>
          <surface>
            <contact>
              <ode/>
            </contact>
            <friction>
              <ode/>
              <torsional>
                <ode/>
              </torsional>
            </friction>
            <bounce/>
          </surface>
          <max_contacts>10</max_contacts>
        </collision>
        <collision name='rh_ffmiddle_collision_2'>
          <pose frame=''>0 0 0.025 0 -0 0</pose>
          <geometry>
            <sphere>
              <radius>0.007</radius>
            </sphere>
          </geometry>
          <surface>
            <contact>
              <ode/>
            </contact>
            <friction>
              <ode/>
              <torsional>
                <ode/>
              </torsional>
            </friction>
            <bounce/>
          </surface>
          <max_contacts>10</max_contacts>
        </collision>
        <visual name='rh_ffmiddle_visual'>
          <pose frame=''>0 0 0 0 -0 0</pose>
          <geometry>
            <mesh>
              <scale>1 1 1</scale>
              <uri>/home/brhm/DUC/RobotArm/src/my_arm/meshes/shadow_hand/hand/F2.dae</uri>
            </mesh>
          </geometry>
          <material>
            <script>
              <uri>__default__</uri>
              <name>__default__</name>
            </script>
          </material>
        </visual>
        <gravity>1</gravity>
        <velocity_decay/>
        <self_collide>1</self_collide>
        <sensor name='rh_ffmiddle_contact' type='contact'>
          <always_on>1</always_on>
          <update_rate>1000</update_rate>
          <contact>
            <collision>rh_ffmiddle_collision</collision>
            <topic>rh_ffmiddle_collision</topic>
          </contact>
          <plugin name='rh_ffproximal_gazebo_ros_bumper_controller' filename='libgazebo_ros_bumper.so'>
            <alwaysOn>true</alwaysOn>
            <frameName>rh_ffmiddle</frameName>
            <updateRate>100.0</updateRate>
            <bumperTopicName>contacts/rh_ff/middle</bumperTopicName>
            <robotNamespace>/</robotNamespace>
          </plugin>
        </sensor>
        <kinematic>0</kinematic>
      </link>
      <joint name='rh_FFJ2' type='revolute'>
        <child>rh_ffmiddle</child>
        <parent>rh_ffproximal</parent>
        <axis>
          <xyz>1 0 0</xyz>
          <limit>
            <lower>0</lower>
            <upper>1.5708</upper>
            <effort>2</effort>
            <velocity>2</velocity>
          </limit>
          <dynamics>
            <damping>0.1</damping>
            <friction>0</friction>
            <spring_reference>0</spring_reference>
            <spring_stiffness>0</spring_stiffness>
          </dynamics>
          <use_parent_model_frame>1</use_parent_model_frame>
        </axis>
        <physics>
          <provide_feedback>1</provide_feedback>
          <ode>
            <provide_feedback>1</provide_feedback>
            <implicit_spring_damper>1</implicit_spring_damper>
            <cfm_damping>1</cfm_damping>
            <limit>
              <cfm>0</cfm>
              <erp>0.2</erp>
            </limit>
          </ode>
        </physics>
      </joint>
      <link name='rh_ffdistal'>
        <pose frame=''>0.033 -0.01 0.412 0 -0 0</pose>
        <inertial>
          <pose frame=''>0 0 0.013077 0 -0 0</pose>
          <mass>0.013</mass>
          <inertia>
            <ixx>1.12092e-06</ixx>
            <ixy>0</ixy>
            <ixz>0</ixz>
            <iyy>1.28092e-06</iyy>
            <iyz>0</iyz>
            <izz>5.3e-07</izz>
          </inertia>
        </inertial>
        <collision name='rh_ffdistal_collision'>
          <pose frame=''>0 0 0 0 -0 0</pose>
          <geometry>
            <mesh>
              <scale>1 1 1</scale>
              <uri>/home/brhm/DUC/RobotArm/src/my_arm/meshes/shadow_hand/hand/F1.dae</uri>
            </mesh>
          </geometry>
          <surface>
            <contact>
              <ode>
                <kp>1e+07</kp>
                <kd>1</kd>
              </ode>
            </contact>
            <friction>
              <ode>
                <mu>500</mu>
                <mu2>500</mu2>
              </ode>
              <torsional>
                <ode/>
              </torsional>
            </friction>
            <bounce/>
          </surface>
          <max_contacts>10</max_contacts>
        </collision>
        <visual name='rh_ffdistal_visual'>
          <pose frame=''>0 0 0 0 -0 0</pose>
          <geometry>
            <mesh>
              <scale>1 1 1</scale>
              <uri>/home/brhm/DUC/RobotArm/src/my_arm/meshes/shadow_hand/hand/F1.dae</uri>
            </mesh>
          </geometry>
          <material>
            <script>
              <uri>__default__</uri>
              <name>__default__</name>
            </script>
          </material>
        </visual>
        <gravity>1</gravity>
        <velocity_decay/>
        <self_collide>1</self_collide>
        <sensor name='rh_ffdistal_contact' type='contact'>
          <always_on>1</always_on>
          <update_rate>1000</update_rate>
          <contact>
            <collision>rh_ffdistal_collision</collision>
            <topic>rh_ffdistal_collision</topic>
          </contact>
          <plugin name='rh_ffdistal_gazebo_ros_bumper_controller' filename='libgazebo_ros_bumper.so'>
            <alwaysOn>true</alwaysOn>
            <frameName>rh_ffdistal</frameName>
            <updateRate>100.0</updateRate>
            <bumperTopicName>contacts/rh_ff/distal</bumperTopicName>
            <robotNamespace>/</robotNamespace>
          </plugin>
        </sensor>
        <kinematic>0</kinematic>
      </link>
      <joint name='rh_FFJ1' type='revolute'>
        <child>rh_ffdistal</child>
        <parent>rh_ffmiddle</parent>
        <axis>
          <xyz>1 0 0</xyz>
          <limit>
            <lower>0</lower>
            <upper>1.5708</upper>
            <effort>2</effort>
            <velocity>2</velocity>
          </limit>
          <dynamics>
            <damping>0.1</damping>
            <friction>0</friction>
            <spring_reference>0</spring_reference>
            <spring_stiffness>0</spring_stiffness>
          </dynamics>
          <use_parent_model_frame>1</use_parent_model_frame>
        </axis>
        <physics>
          <provide_feedback>1</provide_feedback>
          <ode>
            <provide_feedback>1</provide_feedback>
            <implicit_spring_damper>1</implicit_spring_damper>
            <cfm_damping>1</cfm_damping>
            <limit>
              <cfm>0</cfm>
              <erp>0.2</erp>
            </limit>
          </ode>
        </physics>
      </joint>
      <link name='rh_lfmetacarpal'>
        <pose frame=''>-0.033 -0.01 0.26771 0 -0 0</pose>
        <inertial>
          <pose frame=''>0 0 0.04 0 -0 0</pose>
          <mass>0.03</mass>
          <inertia>
            <ixx>1.45e-05</ixx>
            <ixy>0</ixy>
            <ixz>0</ixz>
            <iyy>1.638e-05</iyy>
            <iyz>0</iyz>
            <izz>4.272e-06</izz>
          </inertia>
        </inertial>
        <collision name='rh_lfmetacarpal_collision'>
          <pose frame=''>0 0 0.038 0 -0 0</pose>
          <geometry>
            <box>
              <size>0.018 0.024 0.04</size>
            </box>
          </geometry>
          <surface>
            <contact>
              <ode/>
            </contact>
            <friction>
              <ode/>
              <torsional>
                <ode/>
              </torsional>
            </friction>
            <bounce/>
          </surface>
          <max_contacts>10</max_contacts>
        </collision>
        <visual name='rh_lfmetacarpal_visual'>
          <pose frame=''>0 0 0 0 -0 0</pose>
          <geometry>
            <mesh>
              <scale>1 1 1</scale>
              <uri>/home/brhm/DUC/RobotArm/src/my_arm/meshes/shadow_hand/hand/lfmetacarpal.dae</uri>
            </mesh>
          </geometry>
          <material>
            <script>
              <uri>__default__</uri>
              <name>__default__</name>
            </script>
          </material>
        </visual>
        <gravity>1</gravity>
        <velocity_decay/>
        <self_collide>1</self_collide>
        <sensor name='rh_lfmetacarpal_contact' type='contact'>
          <always_on>1</always_on>
          <update_rate>1000</update_rate>
          <contact>
            <collision>rh_lfmetacarpal_collision</collision>
            <topic>rh_lfmetacarpal_collision</topic>
          </contact>
          <plugin name='rh_lfmetacarpal_gazebo_ros_bumper_controller' filename='libgazebo_ros_bumper.so'>
            <alwaysOn>true</alwaysOn>
            <frameName>rh_lfmetacarpal</frameName>
            <updateRate>100.0</updateRate>
            <bumperTopicName>contacts/rh_lf/metacarpal</bumperTopicName>
            <robotNamespace>/</robotNamespace>
          </plugin>
        </sensor>
        <kinematic>0</kinematic>
      </link>
      <joint name='rh_LFJ5' type='revolute'>
        <child>rh_lfmetacarpal</child>
        <parent>rh_palm</parent>
        <axis>
          <xyz>0.573576 0 0.819152</xyz>
          <limit>
            <lower>0</lower>
            <upper>0.785398</upper>
            <effort>2</effort>
            <velocity>2</velocity>
          </limit>
          <dynamics>
            <damping>0.1</damping>
            <friction>0</friction>
            <spring_reference>0</spring_reference>
            <spring_stiffness>0</spring_stiffness>
          </dynamics>
          <use_parent_model_frame>1</use_parent_model_frame>
        </axis>
        <physics>
          <provide_feedback>1</provide_feedback>
          <ode>
            <provide_feedback>1</provide_feedback>
            <implicit_spring_damper>1</implicit_spring_damper>
            <cfm_damping>1</cfm_damping>
            <limit>
              <cfm>0</cfm>
              <erp>0.2</erp>
            </limit>
          </ode>
        </physics>
      </joint>
      <link name='rh_lfknuckle'>
        <pose frame=''>-0.033 -0.01 0.3335 0 -0 0</pose>
        <inertial>
          <pose frame=''>0 0 0 0 -0 0</pose>
          <mass>0.008</mass>
          <inertia>
            <ixx>2.6e-07</ixx>
            <ixy>0</ixy>
            <ixz>0</ixz>
            <iyy>2.6e-07</iyy>
            <iyz>0</iyz>
            <izz>3.2e-07</izz>
          </inertia>
        </inertial>
        <collision name='rh_lfknuckle_collision'>
          <pose frame=''>0 0 0 3.14159 1.57079 3.14159</pose>
          <geometry>
            <cylinder>
              <length>0.014</length>
              <radius>0.007</radius>
            </cylinder>
          </geometry>
          <surface>
            <contact>
              <ode/>
            </contact>
            <friction>
              <ode/>
              <torsional>
                <ode/>
              </torsional>
            </friction>
            <bounce/>
          </surface>
          <max_contacts>10</max_contacts>
        </collision>
        <visual name='rh_lfknuckle_visual'>
          <pose frame=''>0 0 0.0005 0 -0 0</pose>
          <geometry>
            <mesh>
              <scale>1 1 1</scale>
              <uri>/home/brhm/DUC/RobotArm/src/my_arm/meshes/shadow_hand/hand/knuckle.dae</uri>
            </mesh>
          </geometry>
          <material>
            <script>
              <name>Gazebo/Grey</name>
              <uri>file://media/materials/scripts/gazebo.material</uri>
            </script>
          </material>
        </visual>
        <gravity>1</gravity>
        <velocity_decay/>
        <self_collide>0</self_collide>
        <sensor name='rh_lfknuckle_contact' type='contact'>
          <always_on>1</always_on>
          <update_rate>1000</update_rate>
          <contact>
            <collision>rh_lfknuckle_collision</collision>
            <topic>rh_lfknuckle_collision</topic>
          </contact>
          <plugin name='rh_lfknuckle_gazebo_ros_bumper_controller' filename='libgazebo_ros_bumper.so'>
            <alwaysOn>true</alwaysOn>
            <frameName>rh_lfknuckle</frameName>
            <updateRate>100.0</updateRate>
            <bumperTopicName>contacts/rh_lf/knuckle</bumperTopicName>
            <robotNamespace>/</robotNamespace>
          </plugin>
        </sensor>
        <kinematic>0</kinematic>
      </link>
      <joint name='rh_LFJ4' type='revolute'>
        <child>rh_lfknuckle</child>
        <parent>rh_lfmetacarpal</parent>
        <axis>
          <xyz>0 1 0</xyz>
          <limit>
            <lower>-0.349066</lower>
            <upper>0.349066</upper>
            <effort>2</effort>
            <velocity>2</velocity>
          </limit>
          <dynamics>
            <damping>0.1</damping>
            <friction>0</friction>
            <spring_reference>0</spring_reference>
            <spring_stiffness>0</spring_stiffness>
          </dynamics>
          <use_parent_model_frame>1</use_parent_model_frame>
        </axis>
        <physics>
          <provide_feedback>1</provide_feedback>
          <ode>
            <provide_feedback>1</provide_feedback>
            <implicit_spring_damper>1</implicit_spring_damper>
            <cfm_damping>1</cfm_damping>
            <limit>
              <cfm>0</cfm>
              <erp>0.2</erp>
            </limit>
          </ode>
        </physics>
      </joint>
      <link name='rh_lfproximal'>
        <pose frame=''>-0.033 -0.01 0.3335 0 -0 0</pose>
        <inertial>
          <pose frame=''>0 0 0.0225 0 -0 0</pose>
          <mass>0.03</mass>
          <inertia>
            <ixx>9.8e-06</ixx>
            <ixy>0</ixy>
            <ixz>0</ixz>
            <iyy>1e-05</iyy>
            <iyz>0</iyz>
            <izz>1.8e-06</izz>
          </inertia>
        </inertial>
        <collision name='rh_lfproximal_collision'>
          <pose frame=''>0 0 0.025 0 -0 0</pose>
          <geometry>
            <cylinder>
              <length>0.04</length>
              <radius>0.007</radius>
            </cylinder>
          </geometry>
          <surface>
            <contact>
              <ode/>
            </contact>
            <friction>
              <ode/>
              <torsional>
                <ode/>
              </torsional>
            </friction>
            <bounce/>
          </surface>
          <max_contacts>10</max_contacts>
        </collision>
        <visual name='rh_lfproximal_visual'>
          <pose frame=''>0 0 0 0 -0 0</pose>
          <geometry>
            <mesh>
              <scale>1 1 1</scale>
              <uri>/home/brhm/DUC/RobotArm/src/my_arm/meshes/shadow_hand/hand/F3.dae</uri>
            </mesh>
          </geometry>
          <material>
            <script>
              <uri>__default__</uri>
              <name>__default__</name>
            </script>
          </material>
        </visual>
        <gravity>1</gravity>
        <velocity_decay/>
        <self_collide>1</self_collide>
        <sensor name='rh_lfproximal_contact' type='contact'>
          <always_on>1</always_on>
          <update_rate>1000</update_rate>
          <contact>
            <collision>rh_lfproximal_collision</collision>
            <topic>rh_lfproximal_collision</topic>
          </contact>
          <plugin name='rh_lfproximal_gazebo_ros_bumper_controller' filename='libgazebo_ros_bumper.so'>
            <alwaysOn>true</alwaysOn>
            <frameName>rh_lfproximal</frameName>
            <updateRate>100.0</updateRate>
            <bumperTopicName>contacts/rh_lf/proximal</bumperTopicName>
            <robotNamespace>/</robotNamespace>
          </plugin>
        </sensor>
        <kinematic>0</kinematic>
      </link>
      <joint name='rh_LFJ3' type='revolute'>
        <child>rh_lfproximal</child>
        <parent>rh_lfknuckle</parent>
        <axis>
          <xyz>1 0 0</xyz>
          <limit>
            <lower>0</lower>
            <upper>1.5708</upper>
            <effort>2</effort>
            <velocity>2</velocity>
          </limit>
          <dynamics>
            <damping>0.1</damping>
            <friction>0</friction>
            <spring_reference>0</spring_reference>
            <spring_stiffness>0</spring_stiffness>
          </dynamics>
          <use_parent_model_frame>1</use_parent_model_frame>
        </axis>
        <physics>
          <provide_feedback>1</provide_feedback>
          <ode>
            <provide_feedback>1</provide_feedback>
            <implicit_spring_damper>1</implicit_spring_damper>
            <cfm_damping>1</cfm_damping>
            <limit>
              <cfm>0</cfm>
              <erp>0.2</erp>
            </limit>
          </ode>
        </physics>
      </joint>
      <link name='rh_lfmiddle'>
        <pose frame=''>-0.033 -0.01 0.3785 0 -0 0</pose>
        <inertial>
          <pose frame=''>0 0 0.0125 0 -0 0</pose>
          <mass>0.017</mass>
          <inertia>
            <ixx>2.6e-06</ixx>
            <ixy>0</ixy>
            <ixz>0</ixz>
            <iyy>2.7e-06</iyy>
            <iyz>0</iyz>
            <izz>8.7e-07</izz>
          </inertia>
        </inertial>
        <collision name='rh_lfmiddle_collision'>
          <pose frame=''>0 0 0.0125 0 -0 0</pose>
          <geometry>
            <cylinder>
              <length>0.025</length>
              <radius>0.007</radius>
            </cylinder>
          </geometry>
          <surface>
            <contact>
              <ode/>
            </contact>
            <friction>
              <ode/>
              <torsional>
                <ode/>
              </torsional>
            </friction>
            <bounce/>
          </surface>
          <max_contacts>10</max_contacts>
        </collision>
        <collision name='rh_lfmiddle_collision_1'>
          <pose frame=''>0 0 0 0 -0 0</pose>
          <geometry>
            <sphere>
              <radius>0.007</radius>
            </sphere>
          </geometry>
          <surface>
            <contact>
              <ode/>
            </contact>
            <friction>
              <ode/>
              <torsional>
                <ode/>
              </torsional>
            </friction>
            <bounce/>
          </surface>
          <max_contacts>10</max_contacts>
        </collision>
        <collision name='rh_lfmiddle_collision_2'>
          <pose frame=''>0 0 0.025 0 -0 0</pose>
          <geometry>
            <sphere>
              <radius>0.007</radius>
            </sphere>
          </geometry>
          <surface>
            <contact>
              <ode/>
            </contact>
            <friction>
              <ode/>
              <torsional>
                <ode/>
              </torsional>
            </friction>
            <bounce/>
          </surface>
          <max_contacts>10</max_contacts>
        </collision>
        <visual name='rh_lfmiddle_visual'>
          <pose frame=''>0 0 0 0 -0 0</pose>
          <geometry>
            <mesh>
              <scale>1 1 1</scale>
              <uri>/home/brhm/DUC/RobotArm/src/my_arm/meshes/shadow_hand/hand/F2.dae</uri>
            </mesh>
          </geometry>
          <material>
            <script>
              <uri>__default__</uri>
              <name>__default__</name>
            </script>
          </material>
        </visual>
        <gravity>1</gravity>
        <velocity_decay/>
        <self_collide>1</self_collide>
        <sensor name='rh_lfmiddle_contact' type='contact'>
          <always_on>1</always_on>
          <update_rate>1000</update_rate>
          <contact>
            <collision>rh_lfmiddle_collision</collision>
            <topic>rh_lfmiddle_collision</topic>
          </contact>
          <plugin name='rh_lfproximal_gazebo_ros_bumper_controller' filename='libgazebo_ros_bumper.so'>
            <alwaysOn>true</alwaysOn>
            <frameName>rh_lfmiddle</frameName>
            <updateRate>100.0</updateRate>
            <bumperTopicName>contacts/rh_lf/middle</bumperTopicName>
            <robotNamespace>/</robotNamespace>
          </plugin>
        </sensor>
        <kinematic>0</kinematic>
      </link>
      <joint name='rh_LFJ2' type='revolute'>
        <child>rh_lfmiddle</child>
        <parent>rh_lfproximal</parent>
        <axis>
          <xyz>1 0 0</xyz>
          <limit>
            <lower>0</lower>
            <upper>1.5708</upper>
            <effort>2</effort>
            <velocity>2</velocity>
          </limit>
          <dynamics>
            <damping>0.1</damping>
            <friction>0</friction>
            <spring_reference>0</spring_reference>
            <spring_stiffness>0</spring_stiffness>
          </dynamics>
          <use_parent_model_frame>1</use_parent_model_frame>
        </axis>
        <physics>
          <provide_feedback>1</provide_feedback>
          <ode>
            <provide_feedback>1</provide_feedback>
            <implicit_spring_damper>1</implicit_spring_damper>
            <cfm_damping>1</cfm_damping>
            <limit>
              <cfm>0</cfm>
              <erp>0.2</erp>
            </limit>
          </ode>
        </physics>
      </joint>
      <link name='rh_lfdistal'>
        <pose frame=''>-0.033 -0.01 0.4035 0 -0 0</pose>
        <inertial>
          <pose frame=''>0 0 0.013077 0 -0 0</pose>
          <mass>0.013</mass>
          <inertia>
            <ixx>1.12092e-06</ixx>
            <ixy>0</ixy>
            <ixz>0</ixz>
            <iyy>1.28092e-06</iyy>
            <iyz>0</iyz>
            <izz>5.3e-07</izz>
          </inertia>
        </inertial>
        <collision name='rh_lfdistal_collision'>
          <pose frame=''>0 0 0 0 -0 0</pose>
          <geometry>
            <mesh>
              <scale>1 1 1</scale>
              <uri>/home/brhm/DUC/RobotArm/src/my_arm/meshes/shadow_hand/hand/F1.dae</uri>
            </mesh>
          </geometry>
          <surface>
            <contact>
              <ode>
                <kp>1e+07</kp>
                <kd>1</kd>
              </ode>
            </contact>
            <friction>
              <ode>
                <mu>500</mu>
                <mu2>500</mu2>
              </ode>
              <torsional>
                <ode/>
              </torsional>
            </friction>
            <bounce/>
          </surface>
          <max_contacts>10</max_contacts>
        </collision>
        <visual name='rh_lfdistal_visual'>
          <pose frame=''>0 0 0 0 -0 0</pose>
          <geometry>
            <mesh>
              <scale>1 1 1</scale>
              <uri>/home/brhm/DUC/RobotArm/src/my_arm/meshes/shadow_hand/hand/F1.dae</uri>
            </mesh>
          </geometry>
          <material>
            <script>
              <uri>__default__</uri>
              <name>__default__</name>
            </script>
          </material>
        </visual>
        <gravity>1</gravity>
        <velocity_decay/>
        <self_collide>1</self_collide>
        <sensor name='rh_lfdistal_contact' type='contact'>
          <always_on>1</always_on>
          <update_rate>1000</update_rate>
          <contact>
            <collision>rh_lfdistal_collision</collision>
            <topic>rh_lfdistal_collision</topic>
          </contact>
          <plugin name='rh_lfdistal_gazebo_ros_bumper_controller' filename='libgazebo_ros_bumper.so'>
            <alwaysOn>true</alwaysOn>
            <frameName>rh_lfdistal</frameName>
            <updateRate>100.0</updateRate>
            <bumperTopicName>contacts/rh_lf/distal</bumperTopicName>
            <robotNamespace>/</robotNamespace>
          </plugin>
        </sensor>
        <kinematic>0</kinematic>
      </link>
      <joint name='rh_LFJ1' type='revolute'>
        <child>rh_lfdistal</child>
        <parent>rh_lfmiddle</parent>
        <axis>
          <xyz>1 0 0</xyz>
          <limit>
            <lower>0</lower>
            <upper>1.5708</upper>
            <effort>2</effort>
            <velocity>2</velocity>
          </limit>
          <dynamics>
            <damping>0.1</damping>
            <friction>0</friction>
            <spring_reference>0</spring_reference>
            <spring_stiffness>0</spring_stiffness>
          </dynamics>
          <use_parent_model_frame>1</use_parent_model_frame>
        </axis>
        <physics>
          <provide_feedback>1</provide_feedback>
          <ode>
            <provide_feedback>1</provide_feedback>
            <implicit_spring_damper>1</implicit_spring_damper>
            <cfm_damping>1</cfm_damping>
            <limit>
              <cfm>0</cfm>
              <erp>0.2</erp>
            </limit>
          </ode>
        </physics>
      </joint>
      <link name='rh_mfknuckle'>
        <pose frame=''>0.011 -0.01 0.346 0 -0 0</pose>
        <inertial>
          <pose frame=''>0 0 0 0 -0 0</pose>
          <mass>0.008</mass>
          <inertia>
            <ixx>2.6e-07</ixx>
            <ixy>0</ixy>
            <ixz>0</ixz>
            <iyy>2.6e-07</iyy>
            <iyz>0</iyz>
            <izz>3.2e-07</izz>
          </inertia>
        </inertial>
        <collision name='rh_mfknuckle_collision'>
          <pose frame=''>0 0 0 3.14159 1.57079 3.14159</pose>
          <geometry>
            <cylinder>
              <length>0.014</length>
              <radius>0.007</radius>
            </cylinder>
          </geometry>
          <surface>
            <contact>
              <ode/>
            </contact>
            <friction>
              <ode/>
              <torsional>
                <ode/>
              </torsional>
            </friction>
            <bounce/>
          </surface>
          <max_contacts>10</max_contacts>
        </collision>
        <visual name='rh_mfknuckle_visual'>
          <pose frame=''>0 0 0.0005 0 -0 0</pose>
          <geometry>
            <mesh>
              <scale>1 1 1</scale>
              <uri>/home/brhm/DUC/RobotArm/src/my_arm/meshes/shadow_hand/hand/knuckle.dae</uri>
            </mesh>
          </geometry>
          <material>
            <script>
              <name>Gazebo/Grey</name>
              <uri>file://media/materials/scripts/gazebo.material</uri>
            </script>
          </material>
        </visual>
        <gravity>1</gravity>
        <velocity_decay/>
        <self_collide>0</self_collide>
        <sensor name='rh_mfknuckle_contact' type='contact'>
          <always_on>1</always_on>
          <update_rate>1000</update_rate>
          <contact>
            <collision>rh_mfknuckle_collision</collision>
            <topic>rh_mfknuckle_collision</topic>
          </contact>
          <plugin name='rh_mfknuckle_gazebo_ros_bumper_controller' filename='libgazebo_ros_bumper.so'>
            <alwaysOn>true</alwaysOn>
            <frameName>rh_mfknuckle</frameName>
            <updateRate>100.0</updateRate>
            <bumperTopicName>contacts/rh_mf/knuckle</bumperTopicName>
            <robotNamespace>/</robotNamespace>
          </plugin>
        </sensor>
        <kinematic>0</kinematic>
      </link>
      <joint name='rh_MFJ4' type='revolute'>
        <child>rh_mfknuckle</child>
        <parent>rh_palm</parent>
        <axis>
          <xyz>0 -1 0</xyz>
          <limit>
            <lower>-0.349066</lower>
            <upper>0.349066</upper>
            <effort>2</effort>
            <velocity>2</velocity>
          </limit>
          <dynamics>
            <damping>0.1</damping>
            <friction>0</friction>
            <spring_reference>0</spring_reference>
            <spring_stiffness>0</spring_stiffness>
          </dynamics>
          <use_parent_model_frame>1</use_parent_model_frame>
        </axis>
        <physics>
          <provide_feedback>1</provide_feedback>
          <ode>
            <provide_feedback>1</provide_feedback>
            <implicit_spring_damper>1</implicit_spring_damper>
            <cfm_damping>1</cfm_damping>
            <limit>
              <cfm>0</cfm>
              <erp>0.2</erp>
            </limit>
          </ode>
        </physics>
      </joint>
      <link name='rh_mfproximal'>
        <pose frame=''>0.011 -0.01 0.346 0 -0 0</pose>
        <inertial>
          <pose frame=''>0 0 0.0225 0 -0 0</pose>
          <mass>0.03</mass>
          <inertia>
            <ixx>9.8e-06</ixx>
            <ixy>0</ixy>
            <ixz>0</ixz>
            <iyy>1e-05</iyy>
            <iyz>0</iyz>
            <izz>1.8e-06</izz>
          </inertia>
        </inertial>
        <collision name='rh_mfproximal_collision'>
          <pose frame=''>0 0 0.025 0 -0 0</pose>
          <geometry>
            <cylinder>
              <length>0.04</length>
              <radius>0.007</radius>
            </cylinder>
          </geometry>
          <surface>
            <contact>
              <ode/>
            </contact>
            <friction>
              <ode/>
              <torsional>
                <ode/>
              </torsional>
            </friction>
            <bounce/>
          </surface>
          <max_contacts>10</max_contacts>
        </collision>
        <visual name='rh_mfproximal_visual'>
          <pose frame=''>0 0 0 0 -0 0</pose>
          <geometry>
            <mesh>
              <scale>1 1 1</scale>
              <uri>/home/brhm/DUC/RobotArm/src/my_arm/meshes/shadow_hand/hand/F3.dae</uri>
            </mesh>
          </geometry>
          <material>
            <script>
              <uri>__default__</uri>
              <name>__default__</name>
            </script>
          </material>
        </visual>
        <gravity>1</gravity>
        <velocity_decay/>
        <self_collide>1</self_collide>
        <sensor name='rh_mfproximal_contact' type='contact'>
          <always_on>1</always_on>
          <update_rate>1000</update_rate>
          <contact>
            <collision>rh_mfproximal_collision</collision>
            <topic>rh_mfproximal_collision</topic>
          </contact>
          <plugin name='rh_mfproximal_gazebo_ros_bumper_controller' filename='libgazebo_ros_bumper.so'>
            <alwaysOn>true</alwaysOn>
            <frameName>rh_mfproximal</frameName>
            <updateRate>100.0</updateRate>
            <bumperTopicName>contacts/rh_mf/proximal</bumperTopicName>
            <robotNamespace>/</robotNamespace>
          </plugin>
        </sensor>
        <kinematic>0</kinematic>
      </link>
      <joint name='rh_MFJ3' type='revolute'>
        <child>rh_mfproximal</child>
        <parent>rh_mfknuckle</parent>
        <axis>
          <xyz>1 0 0</xyz>
          <limit>
            <lower>0</lower>
            <upper>1.5708</upper>
            <effort>2</effort>
            <velocity>2</velocity>
          </limit>
          <dynamics>
            <damping>0.1</damping>
            <friction>0</friction>
            <spring_reference>0</spring_reference>
            <spring_stiffness>0</spring_stiffness>
          </dynamics>
          <use_parent_model_frame>1</use_parent_model_frame>
        </axis>
        <physics>
          <provide_feedback>1</provide_feedback>
          <ode>
            <provide_feedback>1</provide_feedback>
            <implicit_spring_damper>1</implicit_spring_damper>
            <cfm_damping>1</cfm_damping>
            <limit>
              <cfm>0</cfm>
              <erp>0.2</erp>
            </limit>
          </ode>
        </physics>
      </joint>
      <link name='rh_mfmiddle'>
        <pose frame=''>0.011 -0.01 0.391 0 -0 0</pose>
        <inertial>
          <pose frame=''>0 0 0.0125 0 -0 0</pose>
          <mass>0.017</mass>
          <inertia>
            <ixx>2.6e-06</ixx>
            <ixy>0</ixy>
            <ixz>0</ixz>
            <iyy>2.7e-06</iyy>
            <iyz>0</iyz>
            <izz>8.7e-07</izz>
          </inertia>
        </inertial>
        <collision name='rh_mfmiddle_collision'>
          <pose frame=''>0 0 0.0125 0 -0 0</pose>
          <geometry>
            <cylinder>
              <length>0.025</length>
              <radius>0.007</radius>
            </cylinder>
          </geometry>
          <surface>
            <contact>
              <ode/>
            </contact>
            <friction>
              <ode/>
              <torsional>
                <ode/>
              </torsional>
            </friction>
            <bounce/>
          </surface>
          <max_contacts>10</max_contacts>
        </collision>
        <collision name='rh_mfmiddle_collision_1'>
          <pose frame=''>0 0 0 0 -0 0</pose>
          <geometry>
            <sphere>
              <radius>0.007</radius>
            </sphere>
          </geometry>
          <surface>
            <contact>
              <ode/>
            </contact>
            <friction>
              <ode/>
              <torsional>
                <ode/>
              </torsional>
            </friction>
            <bounce/>
          </surface>
          <max_contacts>10</max_contacts>
        </collision>
        <collision name='rh_mfmiddle_collision_2'>
          <pose frame=''>0 0 0.025 0 -0 0</pose>
          <geometry>
            <sphere>
              <radius>0.007</radius>
            </sphere>
          </geometry>
          <surface>
            <contact>
              <ode/>
            </contact>
            <friction>
              <ode/>
              <torsional>
                <ode/>
              </torsional>
            </friction>
            <bounce/>
          </surface>
          <max_contacts>10</max_contacts>
        </collision>
        <visual name='rh_mfmiddle_visual'>
          <pose frame=''>0 0 0 0 -0 0</pose>
          <geometry>
            <mesh>
              <scale>1 1 1</scale>
              <uri>/home/brhm/DUC/RobotArm/src/my_arm/meshes/shadow_hand/hand/F2.dae</uri>
            </mesh>
          </geometry>
          <material>
            <script>
              <uri>__default__</uri>
              <name>__default__</name>
            </script>
          </material>
        </visual>
        <gravity>1</gravity>
        <velocity_decay/>
        <self_collide>1</self_collide>
        <sensor name='rh_mfmiddle_contact' type='contact'>
          <always_on>1</always_on>
          <update_rate>1000</update_rate>
          <contact>
            <collision>rh_mfmiddle_collision</collision>
            <topic>rh_mfmiddle_collision</topic>
          </contact>
          <plugin name='rh_mfproximal_gazebo_ros_bumper_controller' filename='libgazebo_ros_bumper.so'>
            <alwaysOn>true</alwaysOn>
            <frameName>rh_mfmiddle</frameName>
            <updateRate>100.0</updateRate>
            <bumperTopicName>contacts/rh_mf/middle</bumperTopicName>
            <robotNamespace>/</robotNamespace>
          </plugin>
        </sensor>
        <kinematic>0</kinematic>
      </link>
      <joint name='rh_MFJ2' type='revolute'>
        <child>rh_mfmiddle</child>
        <parent>rh_mfproximal</parent>
        <axis>
          <xyz>1 0 0</xyz>
          <limit>
            <lower>0</lower>
            <upper>1.5708</upper>
            <effort>2</effort>
            <velocity>2</velocity>
          </limit>
          <dynamics>
            <damping>0.1</damping>
            <friction>0</friction>
            <spring_reference>0</spring_reference>
            <spring_stiffness>0</spring_stiffness>
          </dynamics>
          <use_parent_model_frame>1</use_parent_model_frame>
        </axis>
        <physics>
          <provide_feedback>1</provide_feedback>
          <ode>
            <provide_feedback>1</provide_feedback>
            <implicit_spring_damper>1</implicit_spring_damper>
            <cfm_damping>1</cfm_damping>
            <limit>
              <cfm>0</cfm>
              <erp>0.2</erp>
            </limit>
          </ode>
        </physics>
      </joint>
      <link name='rh_mfdistal'>
        <pose frame=''>0.011 -0.01 0.416 0 -0 0</pose>
        <inertial>
          <pose frame=''>0 0 0.013077 0 -0 0</pose>
          <mass>0.013</mass>
          <inertia>
            <ixx>1.12092e-06</ixx>
            <ixy>0</ixy>
            <ixz>0</ixz>
            <iyy>1.28092e-06</iyy>
            <iyz>0</iyz>
            <izz>5.3e-07</izz>
          </inertia>
        </inertial>
        <collision name='rh_mfdistal_collision'>
          <pose frame=''>0 0 0 0 -0 0</pose>
          <geometry>
            <mesh>
              <scale>1 1 1</scale>
              <uri>/home/brhm/DUC/RobotArm/src/my_arm/meshes/shadow_hand/hand/F1.dae</uri>
            </mesh>
          </geometry>
          <surface>
            <contact>
              <ode>
                <kp>1e+07</kp>
                <kd>1</kd>
              </ode>
            </contact>
            <friction>
              <ode>
                <mu>500</mu>
                <mu2>500</mu2>
              </ode>
              <torsional>
                <ode/>
              </torsional>
            </friction>
            <bounce/>
          </surface>
          <max_contacts>10</max_contacts>
        </collision>
        <visual name='rh_mfdistal_visual'>
          <pose frame=''>0 0 0 0 -0 0</pose>
          <geometry>
            <mesh>
              <scale>1 1 1</scale>
              <uri>/home/brhm/DUC/RobotArm/src/my_arm/meshes/shadow_hand/hand/F1.dae</uri>
            </mesh>
          </geometry>
          <material>
            <script>
              <uri>__default__</uri>
              <name>__default__</name>
            </script>
          </material>
        </visual>
        <gravity>1</gravity>
        <velocity_decay/>
        <self_collide>1</self_collide>
        <sensor name='rh_mfdistal_contact' type='contact'>
          <always_on>1</always_on>
          <update_rate>1000</update_rate>
          <contact>
            <collision>rh_mfdistal_collision</collision>
            <topic>rh_mfdistal_collision</topic>
          </contact>
          <plugin name='rh_mfdistal_gazebo_ros_bumper_controller' filename='libgazebo_ros_bumper.so'>
            <alwaysOn>true</alwaysOn>
            <frameName>rh_mfdistal</frameName>
            <updateRate>100.0</updateRate>
            <bumperTopicName>contacts/rh_mf/distal</bumperTopicName>
            <robotNamespace>/</robotNamespace>
          </plugin>
        </sensor>
        <kinematic>0</kinematic>
      </link>
      <joint name='rh_MFJ1' type='revolute'>
        <child>rh_mfdistal</child>
        <parent>rh_mfmiddle</parent>
        <axis>
          <xyz>1 0 0</xyz>
          <limit>
            <lower>0</lower>
            <upper>1.5708</upper>
            <effort>2</effort>
            <velocity>2</velocity>
          </limit>
          <dynamics>
            <damping>0.1</damping>
            <friction>0</friction>
            <spring_reference>0</spring_reference>
            <spring_stiffness>0</spring_stiffness>
          </dynamics>
          <use_parent_model_frame>1</use_parent_model_frame>
        </axis>
        <physics>
          <provide_feedback>1</provide_feedback>
          <ode>
            <provide_feedback>1</provide_feedback>
            <implicit_spring_damper>1</implicit_spring_damper>
            <cfm_damping>1</cfm_damping>
            <limit>
              <cfm>0</cfm>
              <erp>0.2</erp>
            </limit>
          </ode>
        </physics>
      </joint>
      <link name='rh_rfknuckle'>
        <pose frame=''>-0.011 -0.01 0.342 0 -0 0</pose>
        <inertial>
          <pose frame=''>0 0 0 0 -0 0</pose>
          <mass>0.008</mass>
          <inertia>
            <ixx>2.6e-07</ixx>
            <ixy>0</ixy>
            <ixz>0</ixz>
            <iyy>2.6e-07</iyy>
            <iyz>0</iyz>
            <izz>3.2e-07</izz>
          </inertia>
        </inertial>
        <collision name='rh_rfknuckle_collision'>
          <pose frame=''>0 0 0 3.14159 1.57079 3.14159</pose>
          <geometry>
            <cylinder>
              <length>0.014</length>
              <radius>0.007</radius>
            </cylinder>
          </geometry>
          <surface>
            <contact>
              <ode/>
            </contact>
            <friction>
              <ode/>
              <torsional>
                <ode/>
              </torsional>
            </friction>
            <bounce/>
          </surface>
          <max_contacts>10</max_contacts>
        </collision>
        <visual name='rh_rfknuckle_visual'>
          <pose frame=''>0 0 0.0005 0 -0 0</pose>
          <geometry>
            <mesh>
              <scale>1 1 1</scale>
              <uri>/home/brhm/DUC/RobotArm/src/my_arm/meshes/shadow_hand/hand/knuckle.dae</uri>
            </mesh>
          </geometry>
          <material>
            <script>
              <name>Gazebo/Grey</name>
              <uri>file://media/materials/scripts/gazebo.material</uri>
            </script>
          </material>
        </visual>
        <gravity>1</gravity>
        <velocity_decay/>
        <self_collide>0</self_collide>
        <sensor name='rh_rfknuckle_contact' type='contact'>
          <always_on>1</always_on>
          <update_rate>1000</update_rate>
          <contact>
            <collision>rh_rfknuckle_collision</collision>
            <topic>rh_rfknuckle_collision</topic>
          </contact>
          <plugin name='rh_rfknuckle_gazebo_ros_bumper_controller' filename='libgazebo_ros_bumper.so'>
            <alwaysOn>true</alwaysOn>
            <frameName>rh_rfknuckle</frameName>
            <updateRate>100.0</updateRate>
            <bumperTopicName>contacts/rh_rf/knuckle</bumperTopicName>
            <robotNamespace>/</robotNamespace>
          </plugin>
        </sensor>
        <kinematic>0</kinematic>
      </link>
      <joint name='rh_RFJ4' type='revolute'>
        <child>rh_rfknuckle</child>
        <parent>rh_palm</parent>
        <axis>
          <xyz>0 1 0</xyz>
          <limit>
            <lower>-0.349066</lower>
            <upper>0.349066</upper>
            <effort>2</effort>
            <velocity>2</velocity>
          </limit>
          <dynamics>
            <damping>0.1</damping>
            <friction>0</friction>
            <spring_reference>0</spring_reference>
            <spring_stiffness>0</spring_stiffness>
          </dynamics>
          <use_parent_model_frame>1</use_parent_model_frame>
        </axis>
        <physics>
          <provide_feedback>1</provide_feedback>
          <ode>
            <provide_feedback>1</provide_feedback>
            <implicit_spring_damper>1</implicit_spring_damper>
            <cfm_damping>1</cfm_damping>
            <limit>
              <cfm>0</cfm>
              <erp>0.2</erp>
            </limit>
          </ode>
        </physics>
      </joint>
      <link name='rh_rfproximal'>
        <pose frame=''>-0.011 -0.01 0.342 0 -0 0</pose>
        <inertial>
          <pose frame=''>0 0 0.0225 0 -0 0</pose>
          <mass>0.03</mass>
          <inertia>
            <ixx>9.8e-06</ixx>
            <ixy>0</ixy>
            <ixz>0</ixz>
            <iyy>1e-05</iyy>
            <iyz>0</iyz>
            <izz>1.8e-06</izz>
          </inertia>
        </inertial>
        <collision name='rh_rfproximal_collision'>
          <pose frame=''>0 0 0.025 0 -0 0</pose>
          <geometry>
            <cylinder>
              <length>0.04</length>
              <radius>0.007</radius>
            </cylinder>
          </geometry>
          <surface>
            <contact>
              <ode/>
            </contact>
            <friction>
              <ode/>
              <torsional>
                <ode/>
              </torsional>
            </friction>
            <bounce/>
          </surface>
          <max_contacts>10</max_contacts>
        </collision>
        <visual name='rh_rfproximal_visual'>
          <pose frame=''>0 0 0 0 -0 0</pose>
          <geometry>
            <mesh>
              <scale>1 1 1</scale>
              <uri>/home/brhm/DUC/RobotArm/src/my_arm/meshes/shadow_hand/hand/F3.dae</uri>
            </mesh>
          </geometry>
          <material>
            <script>
              <uri>__default__</uri>
              <name>__default__</name>
            </script>
          </material>
        </visual>
        <gravity>1</gravity>
        <velocity_decay/>
        <self_collide>1</self_collide>
        <sensor name='rh_rfproximal_contact' type='contact'>
          <always_on>1</always_on>
          <update_rate>1000</update_rate>
          <contact>
            <collision>rh_rfproximal_collision</collision>
            <topic>rh_rfproximal_collision</topic>
          </contact>
          <plugin name='rh_rfproximal_gazebo_ros_bumper_controller' filename='libgazebo_ros_bumper.so'>
            <alwaysOn>true</alwaysOn>
            <frameName>rh_rfproximal</frameName>
            <updateRate>100.0</updateRate>
            <bumperTopicName>contacts/rh_rf/proximal</bumperTopicName>
            <robotNamespace>/</robotNamespace>
          </plugin>
        </sensor>
        <kinematic>0</kinematic>
      </link>
      <joint name='rh_RFJ3' type='revolute'>
        <child>rh_rfproximal</child>
        <parent>rh_rfknuckle</parent>
        <axis>
          <xyz>1 0 0</xyz>
          <limit>
            <lower>0</lower>
            <upper>1.5708</upper>
            <effort>2</effort>
            <velocity>2</velocity>
          </limit>
          <dynamics>
            <damping>0.1</damping>
            <friction>0</friction>
            <spring_reference>0</spring_reference>
            <spring_stiffness>0</spring_stiffness>
          </dynamics>
          <use_parent_model_frame>1</use_parent_model_frame>
        </axis>
        <physics>
          <provide_feedback>1</provide_feedback>
          <ode>
            <provide_feedback>1</provide_feedback>
            <implicit_spring_damper>1</implicit_spring_damper>
            <cfm_damping>1</cfm_damping>
            <limit>
              <cfm>0</cfm>
              <erp>0.2</erp>
            </limit>
          </ode>
        </physics>
      </joint>
      <link name='rh_rfmiddle'>
        <pose frame=''>-0.011 -0.01 0.387 0 -0 0</pose>
        <inertial>
          <pose frame=''>0 0 0.0125 0 -0 0</pose>
          <mass>0.017</mass>
          <inertia>
            <ixx>2.6e-06</ixx>
            <ixy>0</ixy>
            <ixz>0</ixz>
            <iyy>2.7e-06</iyy>
            <iyz>0</iyz>
            <izz>8.7e-07</izz>
          </inertia>
        </inertial>
        <collision name='rh_rfmiddle_collision'>
          <pose frame=''>0 0 0.0125 0 -0 0</pose>
          <geometry>
            <cylinder>
              <length>0.025</length>
              <radius>0.007</radius>
            </cylinder>
          </geometry>
          <surface>
            <contact>
              <ode/>
            </contact>
            <friction>
              <ode/>
              <torsional>
                <ode/>
              </torsional>
            </friction>
            <bounce/>
          </surface>
          <max_contacts>10</max_contacts>
        </collision>
        <collision name='rh_rfmiddle_collision_1'>
          <pose frame=''>0 0 0 0 -0 0</pose>
          <geometry>
            <sphere>
              <radius>0.007</radius>
            </sphere>
          </geometry>
          <surface>
            <contact>
              <ode/>
            </contact>
            <friction>
              <ode/>
              <torsional>
                <ode/>
              </torsional>
            </friction>
            <bounce/>
          </surface>
          <max_contacts>10</max_contacts>
        </collision>
        <collision name='rh_rfmiddle_collision_2'>
          <pose frame=''>0 0 0.025 0 -0 0</pose>
          <geometry>
            <sphere>
              <radius>0.007</radius>
            </sphere>
          </geometry>
          <surface>
            <contact>
              <ode/>
            </contact>
            <friction>
              <ode/>
              <torsional>
                <ode/>
              </torsional>
            </friction>
            <bounce/>
          </surface>
          <max_contacts>10</max_contacts>
        </collision>
        <visual name='rh_rfmiddle_visual'>
          <pose frame=''>0 0 0 0 -0 0</pose>
          <geometry>
            <mesh>
              <scale>1 1 1</scale>
              <uri>/home/brhm/DUC/RobotArm/src/my_arm/meshes/shadow_hand/hand/F2.dae</uri>
            </mesh>
          </geometry>
          <material>
            <script>
              <uri>__default__</uri>
              <name>__default__</name>
            </script>
          </material>
        </visual>
        <gravity>1</gravity>
        <velocity_decay/>
        <self_collide>1</self_collide>
        <sensor name='rh_rfmiddle_contact' type='contact'>
          <always_on>1</always_on>
          <update_rate>1000</update_rate>
          <contact>
            <collision>rh_rfmiddle_collision</collision>
            <topic>rh_rfmiddle_collision</topic>
          </contact>
          <plugin name='rh_rfproximal_gazebo_ros_bumper_controller' filename='libgazebo_ros_bumper.so'>
            <alwaysOn>true</alwaysOn>
            <frameName>rh_rfmiddle</frameName>
            <updateRate>100.0</updateRate>
            <bumperTopicName>contacts/rh_rf/middle</bumperTopicName>
            <robotNamespace>/</robotNamespace>
          </plugin>
        </sensor>
        <kinematic>0</kinematic>
      </link>
      <joint name='rh_RFJ2' type='revolute'>
        <child>rh_rfmiddle</child>
        <parent>rh_rfproximal</parent>
        <axis>
          <xyz>1 0 0</xyz>
          <limit>
            <lower>0</lower>
            <upper>1.5708</upper>
            <effort>2</effort>
            <velocity>2</velocity>
          </limit>
          <dynamics>
            <damping>0.1</damping>
            <friction>0</friction>
            <spring_reference>0</spring_reference>
            <spring_stiffness>0</spring_stiffness>
          </dynamics>
          <use_parent_model_frame>1</use_parent_model_frame>
        </axis>
        <physics>
          <provide_feedback>1</provide_feedback>
          <ode>
            <provide_feedback>1</provide_feedback>
            <implicit_spring_damper>1</implicit_spring_damper>
            <cfm_damping>1</cfm_damping>
            <limit>
              <cfm>0</cfm>
              <erp>0.2</erp>
            </limit>
          </ode>
        </physics>
      </joint>
      <link name='rh_rfdistal'>
        <pose frame=''>-0.011 -0.01 0.412 0 -0 0</pose>
        <inertial>
          <pose frame=''>0 0 0.013077 0 -0 0</pose>
          <mass>0.013</mass>
          <inertia>
            <ixx>1.12092e-06</ixx>
            <ixy>0</ixy>
            <ixz>0</ixz>
            <iyy>1.28092e-06</iyy>
            <iyz>0</iyz>
            <izz>5.3e-07</izz>
          </inertia>
        </inertial>
        <collision name='rh_rfdistal_collision'>
          <pose frame=''>0 0 0 0 -0 0</pose>
          <geometry>
            <mesh>
              <scale>1 1 1</scale>
              <uri>/home/brhm/DUC/RobotArm/src/my_arm/meshes/shadow_hand/hand/F1.dae</uri>
            </mesh>
          </geometry>
          <surface>
            <contact>
              <ode>
                <kp>1e+07</kp>
                <kd>1</kd>
              </ode>
            </contact>
            <friction>
              <ode>
                <mu>500</mu>
                <mu2>500</mu2>
              </ode>
              <torsional>
                <ode/>
              </torsional>
            </friction>
            <bounce/>
          </surface>
          <max_contacts>10</max_contacts>
        </collision>
        <visual name='rh_rfdistal_visual'>
          <pose frame=''>0 0 0 0 -0 0</pose>
          <geometry>
            <mesh>
              <scale>1 1 1</scale>
              <uri>/home/brhm/DUC/RobotArm/src/my_arm/meshes/shadow_hand/hand/F1.dae</uri>
            </mesh>
          </geometry>
          <material>
            <script>
              <uri>__default__</uri>
              <name>__default__</name>
            </script>
          </material>
        </visual>
        <gravity>1</gravity>
        <velocity_decay/>
        <self_collide>1</self_collide>
        <sensor name='rh_rfdistal_contact' type='contact'>
          <always_on>1</always_on>
          <update_rate>1000</update_rate>
          <contact>
            <collision>rh_rfdistal_collision</collision>
            <topic>rh_rfdistal_collision</topic>
          </contact>
          <plugin name='rh_rfdistal_gazebo_ros_bumper_controller' filename='libgazebo_ros_bumper.so'>
            <alwaysOn>true</alwaysOn>
            <frameName>rh_rfdistal</frameName>
            <updateRate>100.0</updateRate>
            <bumperTopicName>contacts/rh_rf/distal</bumperTopicName>
            <robotNamespace>/</robotNamespace>
          </plugin>
        </sensor>
        <kinematic>0</kinematic>
      </link>
      <joint name='rh_RFJ1' type='revolute'>
        <child>rh_rfdistal</child>
        <parent>rh_rfmiddle</parent>
        <axis>
          <xyz>1 0 0</xyz>
          <limit>
            <lower>0</lower>
            <upper>1.5708</upper>
            <effort>2</effort>
            <velocity>2</velocity>
          </limit>
          <dynamics>
            <damping>0.1</damping>
            <friction>0</friction>
            <spring_reference>0</spring_reference>
            <spring_stiffness>0</spring_stiffness>
          </dynamics>
          <use_parent_model_frame>1</use_parent_model_frame>
        </axis>
        <physics>
          <provide_feedback>1</provide_feedback>
          <ode>
            <provide_feedback>1</provide_feedback>
            <implicit_spring_damper>1</implicit_spring_damper>
            <cfm_damping>1</cfm_damping>
            <limit>
              <cfm>0</cfm>
              <erp>0.2</erp>
            </limit>
          </ode>
        </physics>
      </joint>
      <link name='rh_thbase'>
        <pose frame=''>0.034 -0.0185 0.276 0 0.785398 0</pose>
        <inertial>
          <pose frame=''>0 0 0 0 -0 0</pose>
          <mass>0.01</mass>
          <inertia>
            <ixx>1.6e-07</ixx>
            <ixy>0</ixy>
            <ixz>0</ixz>
            <iyy>1.6e-07</iyy>
            <iyz>0</iyz>
            <izz>1.6e-07</izz>
          </inertia>
        </inertial>
        <collision name='rh_thbase_collision'>
          <pose frame=''>0 0 0 0 -0 0</pose>
          <geometry>
            <sphere>
              <radius>0.011</radius>
            </sphere>
          </geometry>
          <surface>
            <contact>
              <ode/>
            </contact>
            <friction>
              <ode/>
              <torsional>
                <ode/>
              </torsional>
            </friction>
            <bounce/>
          </surface>
          <max_contacts>10</max_contacts>
        </collision>
        <visual name='rh_thbase_visual'>
          <pose frame=''>0 0 0 0 -0 0</pose>
          <geometry>
            <box>
              <size>0.001 0.001 0.001</size>
            </box>
          </geometry>
          <material>
            <script>
              <uri>__default__</uri>
              <name>__default__</name>
            </script>
          </material>
        </visual>
        <gravity>1</gravity>
        <velocity_decay/>
        <self_collide>0</self_collide>
        <sensor name='rh_thbase_contact' type='contact'>
          <always_on>1</always_on>
          <update_rate>1000</update_rate>
          <contact>
            <collision>rh_thbase_collision</collision>
            <topic>rh_thbase_collision</topic>
          </contact>
          <plugin name='rh_thbase_gazebo_ros_bumper_controller' filename='libgazebo_ros_bumper.so'>
            <alwaysOn>true</alwaysOn>
            <frameName>rh_thbase</frameName>
            <updateRate>100.0</updateRate>
            <bumperTopicName>contacts/rh_th/base</bumperTopicName>
            <robotNamespace>/</robotNamespace>
          </plugin>
        </sensor>
        <kinematic>0</kinematic>
      </link>
      <joint name='rh_THJ5' type='revolute'>
        <child>rh_thbase</child>
        <parent>rh_palm</parent>
        <axis>
          <xyz>-0.707107 0 -0.707107</xyz>
          <limit>
            <lower>-1.0472</lower>
            <upper>1.0472</upper>
            <effort>5</effort>
            <velocity>4</velocity>
          </limit>
          <dynamics>
            <damping>0.2</damping>
            <friction>0</friction>
            <spring_reference>0</spring_reference>
            <spring_stiffness>0</spring_stiffness>
          </dynamics>
          <use_parent_model_frame>1</use_parent_model_frame>
        </axis>
        <physics>
          <provide_feedback>1</provide_feedback>
          <ode>
            <provide_feedback>1</provide_feedback>
            <implicit_spring_damper>1</implicit_spring_damper>
            <cfm_damping>1</cfm_damping>
            <limit>
              <cfm>0</cfm>
              <erp>0.2</erp>
            </limit>
          </ode>
        </physics>
      </joint>
      <link name='rh_thproximal'>
        <pose frame=''>0.034 -0.0185 0.276 0 0.785398 0</pose>
        <inertial>
          <pose frame=''>0 0 0.019 0 -0 0</pose>
          <mass>0.04</mass>
          <inertia>
            <ixx>1.36e-05</ixx>
            <ixy>0</ixy>
            <ixz>0</ixz>
            <iyy>1.36e-05</iyy>
            <iyz>0</iyz>
            <izz>3.13e-06</izz>
          </inertia>
        </inertial>
        <collision name='rh_thproximal_collision'>
          <pose frame=''>0 0 0.02 0 -0 0</pose>
          <geometry>
            <cylinder>
              <length>0.018</length>
              <radius>0.012</radius>
            </cylinder>
          </geometry>
          <surface>
            <contact>
              <ode/>
            </contact>
            <friction>
              <ode/>
              <torsional>
                <ode/>
              </torsional>
            </friction>
            <bounce/>
          </surface>
          <max_contacts>10</max_contacts>
        </collision>
        <visual name='rh_thproximal_visual'>
          <pose frame=''>0 0 0 0 -0 0</pose>
          <geometry>
            <mesh>
              <scale>1 1 1</scale>
              <uri>/home/brhm/DUC/RobotArm/src/my_arm/meshes/shadow_hand/hand/TH3_z.dae</uri>
            </mesh>
          </geometry>
          <material>
            <script>
              <uri>__default__</uri>
              <name>__default__</name>
            </script>
          </material>
        </visual>
        <gravity>1</gravity>
        <velocity_decay/>
        <self_collide>0</self_collide>
        <sensor name='rh_thproximal_contact' type='contact'>
          <always_on>1</always_on>
          <update_rate>1000</update_rate>
          <contact>
            <collision>rh_thproximal_collision</collision>
            <topic>rh_thproximal_collision</topic>
          </contact>
          <plugin name='rh_thproximal_gazebo_ros_bumper_controller' filename='libgazebo_ros_bumper.so'>
            <alwaysOn>true</alwaysOn>
            <frameName>rh_thproximal</frameName>
            <updateRate>100.0</updateRate>
            <bumperTopicName>contacts/rh_th/proximal</bumperTopicName>
            <robotNamespace>/</robotNamespace>
          </plugin>
        </sensor>
        <kinematic>0</kinematic>
      </link>
      <joint name='rh_THJ4' type='revolute'>
        <child>rh_thproximal</child>
        <parent>rh_thbase</parent>
        <axis>
          <xyz>0.707107 0 -0.707107</xyz>
          <limit>
            <lower>0</lower>
            <upper>1.22173</upper>
            <effort>3</effort>
            <velocity>4</velocity>
          </limit>
          <dynamics>
            <damping>0.2</damping>
            <friction>0</friction>
            <spring_reference>0</spring_reference>
            <spring_stiffness>0</spring_stiffness>
          </dynamics>
          <use_parent_model_frame>1</use_parent_model_frame>
        </axis>
        <physics>
          <provide_feedback>1</provide_feedback>
          <ode>
            <provide_feedback>1</provide_feedback>
            <implicit_spring_damper>1</implicit_spring_damper>
            <cfm_damping>1</cfm_damping>
            <limit>
              <cfm>0</cfm>
              <erp>0.2</erp>
            </limit>
          </ode>
        </physics>
      </joint>
      <link name='rh_thhub'>
        <pose frame=''>0.06087 -0.0185 0.30287 0 0.785398 0</pose>
        <inertial>
          <pose frame=''>0 0 0 0 -0 0</pose>
          <mass>0.005</mass>
          <inertia>
            <ixx>1e-06</ixx>
            <ixy>0</ixy>
            <ixz>0</ixz>
            <iyy>1e-06</iyy>
            <iyz>0</iyz>
            <izz>3e-07</izz>
          </inertia>
        </inertial>
        <collision name='rh_thhub_collision'>
          <pose frame=''>0 0 0 0 -0 0</pose>
          <geometry>
            <sphere>
              <radius>0.01</radius>
            </sphere>
          </geometry>
          <surface>
            <contact>
              <ode/>
            </contact>
            <friction>
              <ode/>
              <torsional>
                <ode/>
              </torsional>
            </friction>
            <bounce/>
          </surface>
          <max_contacts>10</max_contacts>
        </collision>
        <visual name='rh_thhub_visual'>
          <pose frame=''>0 0 0 0 -0 0</pose>
          <geometry>
            <box>
              <size>0.001 0.001 0.001</size>
            </box>
          </geometry>
          <material>
            <script>
              <uri>__default__</uri>
              <name>__default__</name>
            </script>
          </material>
        </visual>
        <gravity>1</gravity>
        <velocity_decay/>
        <self_collide>1</self_collide>
        <sensor name='rh_thhub_contact' type='contact'>
          <always_on>1</always_on>
          <update_rate>1000</update_rate>
          <contact>
            <collision>rh_thhub_collision</collision>
            <topic>rh_thhub_collision</topic>
          </contact>
          <plugin name='rh_thhub_gazebo_ros_bumper_controller' filename='libgazebo_ros_bumper.so'>
            <alwaysOn>true</alwaysOn>
            <frameName>rh_thhub</frameName>
            <updateRate>100.0</updateRate>
            <bumperTopicName>contacts/rh_th/hub</bumperTopicName>
            <robotNamespace>/</robotNamespace>
          </plugin>
        </sensor>
        <kinematic>0</kinematic>
      </link>
      <joint name='rh_THJ3' type='revolute'>
        <child>rh_thhub</child>
        <parent>rh_thproximal</parent>
        <axis>
          <xyz>0.707107 0 -0.707107</xyz>
          <limit>
            <lower>-0.20944</lower>
            <upper>0.20944</upper>
            <effort>2</effort>
            <velocity>4</velocity>
          </limit>
          <dynamics>
            <damping>0.2</damping>
            <friction>0</friction>
            <spring_reference>0</spring_reference>
            <spring_stiffness>0</spring_stiffness>
          </dynamics>
          <use_parent_model_frame>1</use_parent_model_frame>
        </axis>
        <physics>
          <provide_feedback>1</provide_feedback>
          <ode>
            <provide_feedback>1</provide_feedback>
            <implicit_spring_damper>1</implicit_spring_damper>
            <cfm_damping>1</cfm_damping>
            <limit>
              <cfm>0</cfm>
              <erp>0.2</erp>
            </limit>
          </ode>
        </physics>
      </joint>
      <link name='rh_thmiddle'>
        <pose frame=''>0.06087 -0.0185 0.30287 0 0.785398 0</pose>
        <inertial>
          <pose frame=''>0 0 0.016 0 -0 0</pose>
          <mass>0.02</mass>
          <inertia>
            <ixx>5.1e-06</ixx>
            <ixy>0</ixy>
            <ixz>0</ixz>
            <iyy>5.1e-06</iyy>
            <iyz>0</iyz>
            <izz>1.21e-06</izz>
          </inertia>
        </inertial>
        <collision name='rh_thmiddle_collision'>
          <pose frame=''>0 0 0.012 0 -0 0</pose>
          <geometry>
            <cylinder>
              <length>0.018</length>
              <radius>0.011</radius>
            </cylinder>
          </geometry>
          <surface>
            <contact>
              <ode/>
            </contact>
            <friction>
              <ode/>
              <torsional>
                <ode/>
              </torsional>
            </friction>
            <bounce/>
          </surface>
          <max_contacts>10</max_contacts>
        </collision>
        <collision name='rh_thmiddle_collision_1'>
          <pose frame=''>0 0 0.019 0 -0 0</pose>
          <geometry>
            <sphere>
              <radius>0.011</radius>
            </sphere>
          </geometry>
          <surface>
            <contact>
              <ode/>
            </contact>
            <friction>
              <ode/>
              <torsional>
                <ode/>
              </torsional>
            </friction>
            <bounce/>
          </surface>
          <max_contacts>10</max_contacts>
        </collision>
        <visual name='rh_thmiddle_visual'>
          <pose frame=''>0 0 0 0 -0 0</pose>
          <geometry>
            <mesh>
              <scale>1 1 1</scale>
              <uri>/home/brhm/DUC/RobotArm/src/my_arm/meshes/shadow_hand/hand/TH2_z.dae</uri>
            </mesh>
          </geometry>
          <material>
            <script>
              <uri>__default__</uri>
              <name>__default__</name>
            </script>
          </material>
        </visual>
        <gravity>1</gravity>
        <velocity_decay/>
        <self_collide>1</self_collide>
        <sensor name='rh_thmiddle_contact' type='contact'>
          <always_on>1</always_on>
          <update_rate>1000</update_rate>
          <contact>
            <collision>rh_thmiddle_collision</collision>
            <topic>rh_thmiddle_collision</topic>
          </contact>
          <plugin name='rh_thmiddle_gazebo_ros_bumper_controller' filename='libgazebo_ros_bumper.so'>
            <alwaysOn>true</alwaysOn>
            <frameName>rh_thmiddle</frameName>
            <updateRate>100.0</updateRate>
            <bumperTopicName>contacts/rh_th/middle</bumperTopicName>
            <robotNamespace>/</robotNamespace>
          </plugin>
        </sensor>
        <kinematic>0</kinematic>
      </link>
      <joint name='rh_THJ2' type='revolute'>
        <child>rh_thmiddle</child>
        <parent>rh_thhub</parent>
        <axis>
          <xyz>0 -1 0</xyz>
          <limit>
            <lower>-0.698132</lower>
            <upper>0.698132</upper>
            <effort>2</effort>
            <velocity>2</velocity>
          </limit>
          <dynamics>
            <damping>0.1</damping>
            <friction>0</friction>
            <spring_reference>0</spring_reference>
            <spring_stiffness>0</spring_stiffness>
          </dynamics>
          <use_parent_model_frame>1</use_parent_model_frame>
        </axis>
        <physics>
          <provide_feedback>1</provide_feedback>
          <ode>
            <provide_feedback>1</provide_feedback>
            <implicit_spring_damper>1</implicit_spring_damper>
            <cfm_damping>1</cfm_damping>
            <limit>
              <cfm>0</cfm>
              <erp>0.2</erp>
            </limit>
          </ode>
        </physics>
      </joint>
      <link name='rh_thdistal'>
        <pose frame=''>0.083498 -0.0185 0.325497 -0.785398 0 -1.5708</pose>
        <inertial>
          <pose frame=''>0 0 0.014559 0 -0 0</pose>
          <mass>0.017</mass>
          <inertia>
            <ixx>2.27794e-06</ixx>
            <ixy>0</ixy>
            <ixz>0</ixz>
            <iyy>2.37794e-06</iyy>
            <iyz>0</iyz>
            <izz>1e-06</izz>
          </inertia>
        </inertial>
        <collision name='rh_thdistal_collision'>
          <pose frame=''>0 0 0 0 -0 0</pose>
          <geometry>
            <mesh>
              <scale>1 1 1</scale>
              <uri>/home/brhm/DUC/RobotArm/src/my_arm/meshes/shadow_hand/hand/TH1_z.dae</uri>
            </mesh>
          </geometry>
          <surface>
            <contact>
              <ode>
                <kp>1e+07</kp>
                <kd>1</kd>
              </ode>
            </contact>
            <friction>
              <ode>
                <mu>500</mu>
                <mu2>500</mu2>
              </ode>
              <torsional>
                <ode/>
              </torsional>
            </friction>
            <bounce/>
          </surface>
          <max_contacts>10</max_contacts>
        </collision>
        <visual name='rh_thdistal_visual'>
          <pose frame=''>0 0 0 0 -0 0</pose>
          <geometry>
            <mesh>
              <scale>1 1 1</scale>
              <uri>/home/brhm/DUC/RobotArm/src/my_arm/meshes/shadow_hand/hand/TH1_z.dae</uri>
            </mesh>
          </geometry>
          <material>
            <script>
              <uri>__default__</uri>
              <name>__default__</name>
            </script>
          </material>
        </visual>
        <gravity>1</gravity>
        <velocity_decay/>
        <self_collide>1</self_collide>
        <sensor name='rh_thdistal_contact' type='contact'>
          <always_on>1</always_on>
          <update_rate>1000</update_rate>
          <contact>
            <collision>rh_thdistal_collision</collision>
            <topic>rh_thdistal_collision</topic>
          </contact>
          <plugin name='rh_thdistal_gazebo_ros_bumper_controller' filename='libgazebo_ros_bumper.so'>
            <alwaysOn>true</alwaysOn>
            <frameName>rh_thdistal</frameName>
            <updateRate>100.0</updateRate>
            <bumperTopicName>contacts/rh_th/distal</bumperTopicName>
            <robotNamespace>/</robotNamespace>
          </plugin>
        </sensor>
        <kinematic>0</kinematic>
      </link>
      <joint name='rh_THJ1' type='revolute'>
        <child>rh_thdistal</child>
        <parent>rh_thmiddle</parent>
        <axis>
          <xyz>0 -1 0</xyz>
          <limit>
            <lower>0</lower>
            <upper>1.5708</upper>
            <effort>1</effort>
            <velocity>4</velocity>
          </limit>
          <dynamics>
            <damping>0.2</damping>
            <friction>0</friction>
            <spring_reference>0</spring_reference>
            <spring_stiffness>0</spring_stiffness>
          </dynamics>
          <use_parent_model_frame>1</use_parent_model_frame>
        </axis>
        <physics>
          <provide_feedback>1</provide_feedback>
          <ode>
            <provide_feedback>1</provide_feedback>
            <implicit_spring_damper>1</implicit_spring_damper>
            <cfm_damping>1</cfm_damping>
            <limit>
              <cfm>0</cfm>
              <erp>0.2</erp>
            </limit>
          </ode>
        </physics>
      </joint>
      <static>0</static>
      <plugin name='gazebo_ros_control' filename='libgazebo_ros_control.so'>
        <robotSimType>sr_gazebo_sim/SrGazeboHWSim</robotSimType>
        <robotNamespace>/</robotNamespace>
      </plugin>
      <plugin name='gazebo_my_arm_control' filename='libgazeboRobotArmController.so'>
        <robotNamespace/>
        <robotSimType>my_arm_gazebo_sim/DefaultRobotHWSim</robotSimType>
        <jointName>rh_world_joint, rh_WRJ2, rh_WRJ1, rh_THJ5, rh_THJ4, rh_THJ3, rh_THJ2, rh_THJ1, rh_THtip, rh_FFJ4, rh_FFJ3, rh_FFJ2, rh_FFJ1, rh_MFJ4, rh_MFJ3, rh_MFJ2, rh_MFJ1, rh_RFJ4, rh_RFJ3, rh_RFJ2, rh_RFJ1, rh_LFJ5, rh_LFJ4, rh_LFJ3, rh_LFJ2, rh_LFJ1</jointName>
        <updateRate>100.0</updateRate>
        <alwaysOn>true</alwaysOn>
      </plugin>
      <pose frame=''>0.5 0.5 0 0 -0 0</pose>
    </model>
    <state world_name='default'>
      <sim_time>51 964000000</sim_time>
      <real_time>53 738481447</real_time>
      <wall_time>1489067852 919159322</wall_time>
      <iterations>51964</iterations>
      <model name='ground_plane'>
        <pose frame=''>0 0 0 0 -0 0</pose>
        <scale>1 1 1</scale>
        <link name='link'>
          <pose frame=''>0 0 0 0 -0 0</pose>
          <velocity>0 0 0 0 -0 0</velocity>
          <acceleration>0 0 0 0 -0 0</acceleration>
          <wrench>0 0 0 0 -0 0</wrench>
        </link>
      </model>
      <model name='shadowhand_motor'>
        <pose frame=''>0.5 0.5 0 0 -0 0</pose>
        <scale>1 1 1</scale>
        <link name='rh_ffdistal'>
          <pose frame=''>0.550672 0.417072 0.280131 -2.48968 -0.010574 -0.097566</pose>
          <velocity>0.001427 0.008216 -0.010743 0.241378 -0.009903 0.004584</velocity>
          <acceleration>0.003075 0.037495 0.052012 -1.84323 0.158948 -0.009704</acceleration>
          <wrench>4e-05 0.000487 0.000676 0 -0 0</wrench>
        </link>
        <link name='rh_ffknuckle'>
          <pose frame=''>0.552982 0.445365 0.323332 0.48467 -0.010557 -0.097565</pose>
          <velocity>0.000723 -0.003421 -0.002103 0.283123 -0.014325 0.0048</velocity>
          <acceleration>0.008627 0.110363 0.050172 -0.862525 0.030808 -0.030845</acceleration>
          <wrench>6.9e-05 0.000883 0.000401 0 -0 0</wrench>
        </link>
        <link name='rh_ffmiddle'>
          <pose frame=''>0.549324 0.405717 0.302363 -2.66667 -0.010573 -0.097566</pose>
          <velocity>0.001232 0.00258 -0.013617 0.251521 -0.010983 0.004692</velocity>
          <acceleration>0.005429 0.075413 0.075967 -1.67712 0.122936 0.016487</acceleration>
          <wrench>9.2e-05 0.001282 0.001291 0 -0 0</wrench>
        </link>
        <link name='rh_ffproximal'>
          <pose frame=''>0.552982 0.445366 0.32333 2.05551 -0.010573 -0.097566</pose>
          <velocity>0.000728 -0.003404 -0.002222 0.285544 -0.014515 0.004998</velocity>
          <acceleration>0.007624 0.10225 0.06764 -0.849162 -0.040664 -0.049081</acceleration>
          <wrench>0.000229 0.003067 0.002029 0 -0 0</wrench>
        </link>
        <link name='rh_forearm'>
          <pose frame=''>0.5 0.5 0 0 -0 0</pose>
          <velocity>4e-06 -1.6e-05 0 0 -0 0</velocity>
          <acceleration>0.000192 0.000349 0 0 -0 0</acceleration>
          <wrench>0.000575 0.001048 0 0 -0 0</wrench>
        </link>
        <link name='rh_lfdistal'>
          <pose frame=''>0.505601 0.423002 0.253035 -2.33414 -0.127425 0.644877</pose>
          <velocity>-0.005027 0.0077 -0.006276 0.164325 0.088614 0.014265</velocity>
          <acceleration>0.022706 -1.94142 0.25794 -0.858332 0.933498 -0.499673</acceleration>
          <wrench>0.000295 -0.025238 0.003353 0 -0 0</wrench>
        </link>
        <link name='rh_lfknuckle'>
          <pose frame=''>0.492449 0.428777 0.307978 0.908781 -0.127365 0.644886</pose>
          <velocity>0.000845 -0.003167 -0.002931 0.199255 0.116569 0.021583</velocity>
          <acceleration>-0.090044 -0.113212 -0.053386 1.55293 -0.699771 -0.593404</acceleration>
          <wrench>-0.00072 -0.000906 -0.000427 0 -0 0</wrench>
        </link>
        <link name='rh_lfmetacarpal'>
          <pose frame=''>0.476586 0.480261 0.270219 0.936706 -0.250546 0.479239</pose>
          <velocity>0.000398 -0.001773 -0.000549 0.038608 0.016236 -0.002278</velocity>
          <acceleration>-0.063427 -0.01898 -0.02949 1.22219 -1.23841 0.105916</acceleration>
          <wrench>-0.001903 -0.000569 -0.000885 0 -0 0</wrench>
        </link>
        <link name='rh_lfmiddle'>
          <pose frame=''>0.51268 0.409384 0.27277 -2.49119 -0.127422 0.644877</pose>
          <velocity>-0.002912 0.004382 -0.0093 0.172237 0.095344 0.015593</velocity>
          <acceleration>-0.943774 -2.30364 0.390239 -2.1683 0.099015 0.861863</acceleration>
          <wrench>-0.016044 -0.039162 0.006634 0 -0 0</wrench>
        </link>
        <link name='rh_lfproximal'>
          <pose frame=''>0.492449 0.428778 0.307977 2.47962 -0.127413 0.644886</pose>
          <velocity>0.000837 -0.003134 -0.003003 0.200918 0.117804 0.020736</velocity>
          <acceleration>-0.759389 -1.3113 0.198845 1.89543 -0.307264 0.014904</acceleration>
          <wrench>-0.022782 -0.039339 0.005965 0 -0 0</wrench>
        </link>
        <link name='rh_mfdistal'>
          <pose frame=''>0.529718 0.415086 0.287388 -2.49844 -0.014348 -0.099533</pose>
          <velocity>0.001475 0.007992 -0.010574 0.239978 -0.009351 0.005239</velocity>
          <acceleration>0.003288 0.042449 0.057621 -2.01972 0.202901 -0.039334</acceleration>
          <wrench>4.3e-05 0.000552 0.000749 0 -0 0</wrench>
        </link>
        <link name='rh_mfknuckle'>
          <pose frame=''>0.53193 0.443485 0.330633 0.484631 -0.014332 -0.099532</pose>
          <velocity>0.000768 -0.003582 -0.001968 0.28125 -0.013945 0.005577</velocity>
          <acceleration>0.010686 0.121992 0.054907 -0.942463 0.046527 -0.060251</acceleration>
          <wrench>8.5e-05 0.000976 0.000439 0 -0 0</wrench>
        </link>
        <link name='rh_mfmiddle'>
          <pose frame=''>0.528273 0.403836 0.309667 -2.6709 -0.014348 -0.099533</pose>
          <velocity>0.001299 0.002377 -0.013405 0.250012 -0.010451 0.005384</velocity>
          <acceleration>0.005833 0.084227 0.083525 -1.83358 0.160457 -0.008975</acceleration>
          <wrench>9.9e-05 0.001432 0.00142 0 -0 0</wrench>
        </link>
        <link name='rh_mfproximal'>
          <pose frame=''>0.53193 0.443486 0.330631 2.05547 -0.014347 -0.099533</pose>
          <velocity>0.000773 -0.003565 -0.002086 0.283692 -0.014042 0.005806</velocity>
          <acceleration>0.00892 0.11338 0.074116 -0.91795 0.019328 -0.03331</acceleration>
          <wrench>0.000268 0.003401 0.002223 0 -0 0</wrench>
        </link>
        <link name='rh_palm'>
          <pose frame=''>0.505907 0.48999 0.246481 0.489011 0.17466 4.7e-05</pose>
          <velocity>0.000225 -0.0011 -0.000197 0.028456 0.006525 -0.00088</velocity>
          <acceleration>0.004943 0.058232 0.019323 -0.877159 0.024973 0.023943</acceleration>
          <wrench>0.001483 0.01747 0.005797 0 -0 0</wrench>
        </link>
        <link name='rh_rfdistal'>
          <pose frame=''>0.502049 0.399427 0.286158 3.07629 0.160985 -0.007045</pose>
          <velocity>0.000552 0.00677 -0.012684 0.216691 -0.009923 -0.010651</velocity>
          <acceleration>1.3159 4.07129 -2.20293 2.16772 1.46329 -2.45935</acceleration>
          <wrench>0.017107 0.052927 -0.028638 0 -0 0</wrench>
        </link>
        <link name='rh_rfknuckle'>
          <pose frame=''>0.509651 0.445363 0.330979 0.490817 0.161006 -0.007043</pose>
          <velocity>0.00076 -0.003603 -0.001704 0.234529 -0.006349 -0.013646</velocity>
          <acceleration>0.035613 0.204127 0.107133 0.759001 -0.246523 -2.93914</acceleration>
          <wrench>0.000285 0.001633 0.000857 0 -0 0</wrench>
        </link>
        <link name='rh_rfmiddle'>
          <pose frame=''>0.505971 0.4057 0.310039 2.88686 0.160965 -0.007041</pose>
          <velocity>0.000399 0.001389 -0.011245 0.223335 -0.009966 -0.01173</velocity>
          <acceleration>0.772292 2.09748 -1.91716 -1.7779 1.13807 -0.409441</acceleration>
          <wrench>0.013129 0.035657 -0.032592 0 -0 0</wrench>
        </link>
        <link name='rh_rfproximal'>
          <pose frame=''>0.509651 0.445363 0.330978 2.06164 0.160967 -0.007044</pose>
          <velocity>0.000756 -0.003605 -0.001793 0.237023 -0.00993 -0.013987</velocity>
          <acceleration>0.282765 0.659846 -0.813658 2.04695 -0.933184 -1.7341</acceleration>
          <wrench>0.008483 0.019795 -0.02441 0 -0 0</wrench>
        </link>
        <link name='rh_thbase'>
          <pose frame=''>0.543146 0.468865 0.261852 1.05588 0.050187 1.15104</pose>
          <velocity>0.000306 -0.00158 -0.001059 0.029527 0.006689 -0.000629</velocity>
          <acceleration>0.005845 0.049279 0.024036 -0.838835 -0.027495 0.148421</acceleration>
          <wrench>5.8e-05 0.000493 0.00024 0 -0 0</wrench>
        </link>
        <link name='rh_thdistal'>
          <pose frame=''>0.586639 0.451987 0.210449 3.05767 0.62211 2.76114</pose>
          <velocity>-0.035533 0.014831 -0.036974 0.31846 0.719391 0.010351</velocity>
          <acceleration>-0.024385 -0.002191 0.019222 -0.260399 0.303021 -0.205858</acceleration>
          <wrench>-0.000415 -3.7e-05 0.000327 0 -0 0</wrench>
        </link>
        <link name='rh_thhub'>
          <pose frame=''>0.568348 0.456244 0.236363 2.5164 0.05074 1.15274</pose>
          <velocity>-0.016792 0.006291 -0.022078 0.315356 0.666893 0.00048</velocity>
          <acceleration>-0.009875 0.018007 0.025216 -0.909112 0.474425 0.345227</acceleration>
          <wrench>-4.9e-05 9e-05 0.000126 0 -0 0</wrench>
        </link>
        <link name='rh_thmiddle'>
          <pose frame=''>0.568337 0.456249 0.236352 2.5174 -0.072138 1.2422</pose>
          <velocity>-0.016996 0.006381 -0.022417 0.317126 0.714643 0.010698</velocity>
          <acceleration>-0.015255 0.010873 0.023314 -0.512355 0.353691 0.121146</acceleration>
          <wrench>-0.000305 0.000217 0.000466 0 -0 0</wrench>
        </link>
        <link name='rh_thproximal'>
          <pose frame=''>0.543138 0.468868 0.261841 2.30671 0.050968 1.15267</pose>
          <velocity>0.000159 -0.001548 -0.001372 0.307977 0.663793 -0.00066</velocity>
          <acceleration>-0.002031 0.033693 0.024983 -1.7675 0.877421 0.985737</acceleration>
          <wrench>-8.1e-05 0.001348 0.000999 0 -0 0</wrench>
        </link>
        <link name='rh_wrist'>
          <pose frame=''>0.500003 0.489991 0.212999 1e-06 0.174533 0</pose>
          <velocity>0.000196 -0.00097 -4.2e-05 0.000118 4.3e-05 -2e-06</velocity>
          <acceleration>0.001718 0.028044 3.3e-05 0.000968 0.001234 0.000753</acceleration>
          <wrench>0.000172 0.002804 3e-06 0 -0 0</wrench>
        </link>
      </model>
      <model name='sr_top_view_camera'>
        <pose frame=''>0 0 0 0 -0 0</pose>
        <scale>1 1 1</scale>
        <link name='link'>
          <pose frame=''>0 0 0 0 -0 0</pose>
          <velocity>0 0 0 0 -0 0</velocity>
          <acceleration>0 0 0 0 -0 0</acceleration>
          <wrench>0 0 0 0 -0 0</wrench>
        </link>
      </model>
      <light name='sun'>
        <pose frame=''>0 0 10 0 -0 0</pose>
      </light>
    </state>
    <gui fullscreen='0'>
      <camera name='user_camera'>
        <pose frame=''>1.44655 -0.054191 0.452522 0 0.127643 2.2522</pose>
        <view_controller>orbit</view_controller>
        <projection_type>perspective</projection_type>
      </camera>
    </gui>
  </world>
</sdf>
